Workbook

Sheet     2025학년도 입결 분석    
F1: 2025학년도 정시 입결 (70% 컷) 분석 25. 12. 7 | AH1: 제작 및 검토 < 베텔기우스 > | BA1: =IF(I6="","-non",I6) -> -non
BA2: =IF(I7="","-non",I7) -> -non
AH3: Betelgeuse058.tistory.com
N4: 1. 본 자료는, 25학년도 정시 입결(대학별 환산점수)을 → '25학년도 수능'의 표준점수와 백분위로 역환산한 산출내역입니다. | BA4: =IF(I8="","-non",I8) -> -non
I5: 대학명 강조 | J5: 학과명 강조 | N5: (대학별 환산점수는 각 대학에서 공식 발표한 70%컷 입시결과입니다.) | BA5: =IF(J6="","-non",J6) -> -non
H6: 1 | N6: 2. 모든 학과의 역환산 산출내역(표점입결, 백분위입결)은, 각 대학의 환산공식에 따라 역으로 계산된 자동산출 결과이며, 이는 올해의 원점수 표준점수 백분위점수로 변환 후 예상입결을 산출하는데 사용됩니다. | BA6: =IF(J7="","-non",J7) -> -non
H7: 2 | N7: 3. 국.수.탐 백분위가 동일할때의 역환산 결과이며, 과목별 반영비율에 따른 유불리는 '환산점수 배치표 탭'을 참고 바랍니다. | BA7: =IF(J8="","-non",J8) -> -non
H8: 3 | N8: 4. 실제 입시결과이므로, 일부 학과는 적정한 위치보다 높거나 낮은곳에 위치할 수 있습니다 | AZ8: .
AL9: 의대 감원에 따른 입결변화 예측
M10: 입시결과 역환산 산출내역
B11: 자연 누적 (추정치) | D11: 의대감원 | E11: 25입시결과 | H11: 26수능 표준점수 | I11: 대학 | J11: 학과 | K11: 계열 | L11: 모집인원 | M11: 대학별 | O11: 반영방법 | R11: 반영비율 | U11: 백분위 | V11: 표준점수 | Y11: 변표 | Z11: 등급 점수 | AF11: 가산점 | AH11: 비고 | AN11: 감원 | AO11: 감소인원(누적) | AR11: 누적 백분율 변화
D12: 영향 | E12: 자연→인문 | F12: 계열 | G12: 계열 | M12: 환산점수 / | N12: 만점 | O12: 국.수 | P12: 탐구 | R12: 국 | S12: 수 | T12: 탐 | U12: 국.수.탐 | V12: 국어 | W12: 수학 | X12: 탐구 | Y12: 탐구 | Z12: 영어 | AA12: 점수 | AB12: 한국사 | AC12: 점수 | AD12: 제2외국 | AE12: 점수 | AF12: 미기,과탐 | AN12: 영향력 | AO12: 정시모집+수시합격 예상인원 | AR12: (추정치)
B13: (%) | C13: (명) | D13: (명) | E13: 교차표점 | F13: 백분위 | G13: 표준점수 | AG13: 교과 | AN13: (%) | AO13: 자연+인문 | AP13: 자연 | AQ13: 인문 | BA13: 계열ID
B14: 0.04 | C14: 87 | D14: 0 | F14: 100 | G14: 418.38 | H14: 422.97 | I14: 서울대 | J14: 의예과 | K14: 자연 | L14: 29 | M14: 421.6 / | N14: 600 | O14: 표점 | P14: 표점 | Q14: 2과목 | R14: 33 | S14: 40 | T14: 27 | U14: 100 | V14: 139.12052 | W14: 140.18077 | X14: 69.54 | Z14: 1등급 | AA14: 0 | AB14: 만점 | AC14: 0 | AD14: 만점 | AE14: 0 | AF14: 3 | AG14: 0 | AH14: 물리/화학 필수, 과탐Ⅱ3점 가산 | AL14: 서울대 의예과 | AM14: 자연 | AN14: 100% | AO14: 0 | AP14: 0 | AQ14: 0 | AR14: 0.04 → 0.04 | BA14: 자연1
B15: 0.13 | C15: 282 | D15: 0 | F15: 99.94 | G15: 415.27 | H15: 419.44 | I15: 한양대 | J15: 의예과 | K15: 자연 | L15: 52 | M15: 993.26 / | N15: 1000 | O15: 표점/만점 | P15: 변표/만점 | Q15: 2과목 | R15: 25 | S15: 40 | T15: 25 | U15: 99.94 | V15: 137.91471 | W15: 138.37207 | X15: 69.49 | Y15: 69.97 | Z15: 1등급 | AA15: 100 | AB15: 만점 | AC15: 0 | AD15: 만점 | AE15: 0 | AF15: 0 | AG15: 0 | AL15: 한양대 의예과 | AM15: 자연 | AN15: 100 | AO15: 0 | AP15: 0 | AQ15: 0 | AR15: 0.14 → 0.14 | BA15: 자연2
B16: 0.22 | C16: 477 | D16: 0 | F16: 99.81 | G16: 413.63 | H16: 416.70 | I16: 가톨릭대 | J16: 의예과 | K16: 자연 | L16: 37 | M16: 691.063 / | N16: 1000 | O16: 표점 | P16: 변표 | Q16: 2과목 | R16: 30 | S16: 40 | T16: 30 | U16: 99.81 | V16: 137.0476 | W16: 137.76785 | X16: 69.41 | Y16: 69.99 | Z16: 1등급 | AA16: 0 | AB16: 만점 | AC16: 0 | AD16: 만점 | AE16: 0 | AF16: 0 | AG16: 0 | AH16: 656.51/950만점 | AL16: 가톨릭대 의예과 | AM16: 자연 | AN16: 100 | AO16: 0 | AP16: 0 | AQ16: 0 | AR16: 0.22 → 0.22 | BA16: 자연3
B17: 0.23 | C17: 499 | D17: -61 | F17: 99.77 | G17: 413.33 | H17: 417.28 | I17: 성균관대 | J17: 의예과 | K17: 자연 | L17: 50 | M17: 691.85 / | N17: 1000 | O17: 표점 | P17: 변표 | Q17: 2과목 | R17: 20 | S17: 40 | T17: 30 | U17: 99.77 | V17: 136.92579 | W17: 137.67579 | X17: 69.36 | Y17: 68.6 | Z17: 1등급 | AA17: 63.5 | AB17: 만점 | AC17: 0 | AD17: 만점 | AE17: 0 | AF17: 10.29 | AG17: 0 | AH17: 과탐5%가산 | AL17: 성균관대 의예과 | AM17: 자연 | AN17: 100 | AO17: -61 | AP17: -61 | AQ17: 0 | AR17: 0.23 → 0.20 | BA17: 자연4
B18: 0.25 | C18: 543 | D18: -61 | F18: 99.71 | G18: 412.90 | H18: 416.38 | I18: 연세대 | J18: 의예과 | K18: 자연 | L18: 47 | M18: 658.3 / | N18: 900 | O18: 표점 | P18: 변표 | Q18: 2과목 | R18: 22 | S18: 33 | T18: 33 | U18: 99.71 | V18: 136.78267 | W18: 137.53267 | X18: 69.29 | Y18: 69.65 | Z18: 1등급 | AA18: 100 | AB18: 만점 | AC18: 0 | AD18: 만점 | AE18: 0 | AF18: 6.269 | AG18: 0 | AH18: 과탐3%가산 | AL18: 연세대 의예과 | AM18: 자연 | AN18: 100 | AO18: -61 | AP18: -61 | AQ18: 0 | AR18: 0.25 → 0.22 | BA18: 자연5
B19: 0.29 | C19: 629 | D19: -70 | F19: 99.63 | G19: 412.20 | H19: 414.74 | I19: 서울대 | J19: 치의학과 | K19: 자연 | L19: 11 | M19: 415 / | N19: 600 | O19: 표점 | P19: 표점 | Q19: 2과목 | R19: 33 | S19: 40 | T19: 27 | U19: 99.63 | V19: 136.56352 | W19: 137.31352 | X19: 69.16 | Z19: 1등급 | AA19: 0 | AB19: 만점 | AC19: 0 | AD19: 만점 | AE19: 0 | AF19: 3 | AG19: 0 | AH19: 과탐Ⅱ3점 가산 | AL19: 서울대 치의학과 | AM19: 자연 | AN19: 50% | AO19: -70 | AP19: -70 | AQ19: 0 | AR19: 0.30 → 0.26 | BA19: 자연6
B20: 0.40 | C20: 868 | D20: -135 | F20: 99.46 | G20: 410.76 | H20: 412.71 | I20: 고려대 | J20: 의과대학 | K20: 자연 | L20: 28 | M20: 697.28 / | N20: 1000 | O20: 표점 | P20: 변표 | Q20: 2과목 | R20: 31 | S20: 38 | T20: 31 | U20: 99.46 | V20: 136.14971 | W20: 136.89971 | X20: 68.86 | Y20: 69.72 | Z20: 1등급 | AA20: 0 | AB20: 만점 | AC20: 10 | AD20: 만점 | AE20: 0 | AF20: 0 | AG20: 0 | AL20: 고려대 의과대학 | AM20: 자연 | AN20: 100 | AO20: -135 | AP20: -135 | AQ20: 0 | AR20: 0.41 → 0.34 | BA20: 자연7
B21: 0.42 | C21: 911 | D21: -69 | F21: 99.44 | G21: 410.56 | H21: 411.81 | I21: 서울대 | J21: 수리과학부 | K21: 자연 | L21: 9 | M21: 413.4 / | N21: 600 | O21: 표점 | P21: 표점 | Q21: 2과목 | R21: 33 | S21: 40 | T21: 27 | U21: 99.44 | V21: 136.09109 | W21: 136.84109 | X21: 68.81 | Z21: 1등급 | AA21: 0 | AB21: 만점 | AC21: 0 | AD21: 만점 | AE21: 0 | AF21: 3 | AG21: 0 | AH21: 과탐Ⅱ3점 가산 | AL21: 서울대 수리과학부 | AM21: 자연 | AN21: 30% | AO21: -69 | AP21: -69 | AQ21: 0 | AR21: 0.43 → 0.39 | BA21: 자연8
B22: 0.57 | C22: 1,237 | D22: -125 | F22: 99.26 | G22: 408.97 | H22: 410.52 | I22: 경희대 | J22: 의예과 | K22: 자연 | L22: 45 | M22: 595.35 / | N22: 800 | O22: 표점 | P22: 변표 | Q22: 2과목 | R22: 20 | S22: 35 | T22: 30 | U22: 99.26 | V22: 135.53224 | W22: 136.39918 | X22: 68.52 | Y22: 69.32 | Z22: 1등급 | AA22: 120 | AB22: 만점 | AC22: 0 | AD22: 만점 | AE22: 0 | AF22: 9.6 | AG22: 0 | AH22: 과탐9.6점 가산 | AL22: 경희대 의예과 | AM22: 자연 | AN22: 100 | AO22: -125 | AP22: -125 | AQ22: 0 | AR22: 0.57 → 0.51 | BA22: 자연9
B23: 0.58 | C23: 1,259 | D23: -230 | F23: 99.24 | G23: 408.83 | H23: 410.75 | I23: 중앙대 | J23: 의학부 | K23: 자연 | L23: 42 | M23: 807.4 / | N23: 1000 | O23: 표점 | P23: 변표 | Q23: 2과목 | R23: 30 | S23: 35 | T23: 35 | U23: 99.24 | V23: 135.4705 | W23: 136.35287 | X23: 68.5 | Y23: 69.55 | Z23: 1등급 | AA23: 100 | AB23: 만점 | AC23: 10 | AD23: 만점 | AE23: 0 | AF23: 12.171 | AG23: 0 | AH23: 과탐5%가산 | AL23: 중앙대 의학부 | AM23: 자연 | AN23: 100 | AO23: -230 | AP23: -230 | AQ23: 0 | AR23: 0.58 → 0.47 | BA23: 자연10
B24: 0.59 | C24: 1,280 | D24: -230 | F24: 99.21 | G24: 408.57 | H24: 410.69 | I24: 울산대 | J24: 의예 | K24: 자연 | L24: 12 | M24: 989.25 / | N24: 1000 | O24: 표점/만점 | P24: 표점/만점 | Q24: 2과목 | R24: 20 | S24: 30 | T24: 30 | U24: 99.21 | V24: 135.35832 | W24: 136.26874 | X24: 67.28/67.91 | Z24: 1등급 | AA24: 190 | AB24: 만점 | AC24: 10 | AD24: 만점 | AE24: 0 | AF24: 0 | AG24: 0 | AL24: 울산대 의예 | AM24: 자연 | AN24: 100 | AO24: -230 | AP24: -230 | AQ24: 0 | AR24: 0.59 → 0.48 | BA24: 자연11
B25: 0.59 | C25: 1,280 | D25: -173 | F25: 99.2 | G25: 408.54 | H25: 410.50 | I25: 서울대 | J25: 컴퓨터공학부 | K25: 자연 | L25: 27 | M25: 411.4 / | N25: 600 | O25: 표점 | P25: 표점 | Q25: 2과목 | R25: 33 | S25: 40 | T25: 27 | U25: 99.2 | V25: 135.3416 | W25: 136.2562 | X25: 68.47 | Z25: 1등급 | AA25: 0 | AB25: 만점 | AC25: 0 | AD25: 만점 | AE25: 0 | AF25: 3 | AG25: 0 | AH25: 과탐Ⅱ3점 가산 | AL25: 서울대 컴퓨터공학부 | AM25: 자연 | AN25: 75% | AO25: -173 | AP25: -173 | AQ25: 0 | AR25: 0.60 → 0.52 | BA25: 자연12
B26: 0.68 | C26: 1,476 | D26: -173 | F26: 99.06 | G26: 407.22 | H26: 409.83 | I26: 서울대 | J26: 약학계열 | K26: 자연 | L26: 10 | M26: 410 / | N26: 600 | O26: 표점 | P26: 표점 | Q26: 2과목 | R26: 33 | S26: 40 | T26: 27 | U26: 99.06 | V26: 134.9321 | W26: 135.5926 | X26: 68.35 | Z26: 1등급 | AA26: 0 | AB26: 만점 | AC26: 0 | AD26: 만점 | AE26: 0 | AF26: 3 | AG26: 0 | AH26: 과탐Ⅱ3점 가산 | AL26: 서울대 약학계열 | AM26: 자연 | AN26: 75% | AO26: -173 | AP26: -173 | AQ26: 0 | AR26: 0.68 → 0.60 | BA26: 자연13
B27: 0.67 | C27: 1,454 | D27: -180 | F27: 99.06 | G27: 407.26 | H27: 409.90 | I27: 아주대 | J27: 의학과 | K27: 자연 | L27: 50 | M27: 949.477 / | N27: 950 | O27: 표점/만점 | P27: 변표/만점 | Q27: 2과목 | R27: 20 | S27: 40 | T27: 30 | U27: 99.06 | V27: 134.93664 | W27: 135.61984 | X27: 68.35 | Y27: 69.43 | Z27: 1등급 | AA27: 95 | AB27: 만점 | AC27: 0 | AD27: 만점 | AE27: 0 | AF27: 19.516 | AG27: 0 | AH27: 999.45점/1000만점 미/기/과탐 3% | AL27: 아주대 의학과 | AM27: 자연 | AN27: 100 | AO27: -180 | AP27: -180 | AQ27: 0 | AR27: 0.68 → 0.59 | BA27: 자연14
B28: 0.78 | C28: 1,693 | D28: -90 | E28: 405.67 | F28: 99.04 | G28: 408.24 | H28: 409.46 | I28: 이화여대 | J28: 의예과(인문) | K28: 통합 | L28: 8 | M28: 988.46 / | N28: 1000 | O28: 표점/만점 | P28: 변표/만점 | Q28: 2과목 | R28: 30 | S28: 30 | T28: 20 | U28: 99.04 | V28: 134.90788 | W28: 135.44731 | X28: 68.94 | Y28: 68.86 | Z28: 1등급 | AA28: 200 | AB28: 만점 | AC28: 10 | AD28: 만점 | AE28: 0 | AF28: 0 | AG28: 0 | AL28: 이화여대 의예과(인문) | AM28: 통합 | AN28: 50% | AO28: -90 | AP28: -79 | AQ28: -11 | AR28: 0.79 → 0.75 | BA28: 자연15
B29: 0.69 | C29: 1,497 | D29: -190 | F29: 99.04 | G29: 407.00 | H29: 409.81 | I29: 인제대 | J29: 의예 | K29: 자연 | L29: 19 | M29: 542 / | N29: 800 | O29: 표점 | P29: 표점 | Q29: 2과목 | R29: 25 | S29: 25 | T29: 25 | U29: 99.04 | V29: 134.90457 | W29: 135.42744 | X29: 68.33 | Z29: 1등급 | AA29: 135 | AB29: 만점 | AC29: 0 | AD29: 만점 | AE29: 0 | AF29: 0 | AG29: 0 | AL29: 인제대 의예 | AM29: 자연 | AN29: 100 | AO29: -190 | AP29: -190 | AQ29: 0 | AR29: 0.70 → 0.61 | BA29: 자연16
B30: 0.76 | C30: 1,649 | D30: -190 | F30: 98.92 | G30: 406.00 | H30: 409.65 | I30: 이화여대 | J30: 의예과(자연) | K30: 자연 | L30: 50 | M30: 1003.13 / | N30: 1000 | O30: 표점/만점 | P30: 변표/만점 | Q30: 2과목 | R30: 25 | S30: 30 | T30: 25 | U30: 98.92 | V30: 134.69175 | W30: 134.85842 | X30: 68.22 | Y30: 69.32 | Z30: 1등급 | AA30: 200 | AB30: 만점 | AC30: 10 | AD30: 만점 | AE30: 0 | AF30: 14.827 | AG30: 0 | AH30: 과6% | AL30: 이화여대 의예과(자연) | AM30: 자연 | AN30: 100 | AO30: -190 | AP30: -190 | AQ30: 0 | AR30: 0.76 → 0.67 | BA30: 자연17
B31: 0.76 | C31: 1,649 | D31: -200 | F31: 98.9 | G31: 405.91 | H31: 409.63 | I31: 연세대 | J31: 치의예과 | K31: 자연 | L31: 26 | M31: 721.356 / | N31: 1000 | O31: 표점 | P31: 변표 | Q31: 2과목 | R31: 22 | S31: 33 | T31: 33 | U31: 98.9 | V31: 134.66254 | W31: 134.8292 | X31: 68.21 | Y31: 68.72 | Z31: 1등급 | AA31: 111.11 | AB31: 만점 | AC31: 0 | AD31: 만점 | AE31: 0 | AF31: 6.872 | AG31: 0 | AH31: 과탐3%가산 | AL31: 연세대 치의예과 | AM31: 자연 | AN31: 50% | AO31: -200 | AP31: -200 | AQ31: 0 | AR31: 0.77 → 0.68 | BA31: 자연18
B32: 0.79 | C32: 1,714 | D32: -500 | F32: 98.83 | G32: 405.57 | H32: 410.15 | I32: 충남대 | J32: 의예과 | K32: 자연 | L32: 18 | M32: 202.73 / | N32: 300 | O32: 표점 | P32: 표점 | Q32: 2과목 | R32: 25 | S32: 45 | T32: 30 | U32: 98.83 | V32: 134.55776 | W32: 134.72443 | X32: 68.14 | Z32: 1등급 | AA32: 0 | AB32: 만점 | AC32: 0 | AD32: 만점 | AE32: 0 | AF32: 0 | AG32: 0 | AL32: 충남대 의예과 | AM32: 자연 | AN32: 100 | AO32: -500 | AP32: -500 | AQ32: 0 | AR32: 0.80 → 0.57 | BA32: 자연19
B33: 0.82 | C33: 1,779 | D33: -400 | F33: 98.79 | G33: 405.33 | H33: 409.73 | I33: 경북대 | J33: 의예과 | K33: 자연 | L33: 22 | M33: 728.58 / | N33: 1000 | O33: 표점 | P33: 변표 | Q33: 2과목 | R33: 25 | S33: 38 | T33: 25 | U33: 98.79 | V33: 134.4829 | W33: 134.64956 | X33: 68.1 | Y33: 69.21 | Z33: 1등급 | AA33: 125 | AB33: 만점 | AC33: 10 | AD33: 만점 | AE33: 0 | AF33: 0 | AG33: 0 | AL33: 경북대 의예과 | AM33: 자연 | AN33: 100 | AO33: -400 | AP33: -400 | AQ33: 0 | AR33: 0.82 → 0.64 | BA33: 자연20
B34: 0.83 | C34: 1,801 | D34: -400 | F34: 98.75 | G34: 405.14 | H34: 409.69 | I34: 부산대 | J34: 의예과 | K34: 자연 | L34: 33 | M34: 602.4 / | N34: 800 | O34: 표점 | P34: 표점 | Q34: 2과목 | R34: 20 | S34: 30 | T34: 30 | U34: 98.75 | V34: 134.42436 | W34: 134.59103 | X34: 68.06 | Z34: 1등급 | AA34: 160 | AB34: 만점 | AC34: 10 | AD34: 만점 | AE34: 0 | AF34: 0 | AG34: 0 | AL34: 부산대 의예과 | AM34: 자연 | AN34: 100 | AO34: -400 | AP34: -400 | AQ34: 0 | AR34: 0.84 → 0.65 | BA34: 자연21
B35: 0.85 | C35: 1,845 | D35: -383 | F35: 98.73 | G35: 405.00 | H35: 409.64 | I35: 서울대 | J35: 수의예과 | K35: 자연 | L35: 15 | M35: 407.7 / | N35: 600 | O35: 표점 | P35: 표점 | Q35: 2과목 | R35: 33 | S35: 40 | T35: 27 | U35: 98.73 | V35: 134.38236 | W35: 134.54903 | X35: 68.03 | Z35: 1등급 | AA35: 0 | AB35: 만점 | AC35: 0 | AD35: 만점 | AE35: 0 | AF35: 3 | AG35: 0 | AH35: 과탐Ⅱ3점 가산 | AL35: 서울대 수의예과 | AM35: 자연 | AN35: 75% | AO35: -383 | AP35: -383 | AQ35: 0 | AR35: 0.85 → 0.67 | BA35: 자연22
B36: 0.88 | C36: 1,910 | D36: -250 | F36: 98.63 | G36: 404.46 | H36: 409.02 | I36: 경희대 | J36: 한의예과(통합) | K36: 통합 | L36: 14 | M36: 589.93 / | N36: 800 | O36: 표점 | P36: 변표 | Q36: 2과목 | R36: 35 | S36: 20 | T36: 30 | U36: 98.63 | V36: 134.21618 | W36: 134.38285 | X36: 67.93 | Y36: 68.72 | Z36: 1등급 | AA36: 120 | AB36: 만점 | AC36: 0 | AD36: 만점 | AE36: 0 | AF36: 9.6 | AG36: 0 | AH36: 사탐9.6점 가산 | AL36: 경희대 한의예과(통합) | AM36: 통합 | AN36: 50% | AO36: -250 | AP36: -215 | AQ36: -35 | AR36: 0.89 → 0.79 | BA36: 자연23
B37: 0.88 | C37: 1,910 | D37: -511 | F37: 98.63 | G37: 404.48 | H37: 409.70 | I37: 인하대 | J37: 의예과 | K37: 자연 | L37: 40 | M37: 990.8 / | N37: 1000 | O37: 표점/만점 | P37: 변표/만점 | Q37: 2과목 | R37: 25 | S37: 35 | T37: 30 | U37: 98.63 | V37: 134.22066 | W37: 134.38732 | X37: 67.94 | Y37: 68.72 | Z37: 1등급 | AA37: 100 | AB37: 만점 | AC37: 0 | AD37: 만점 | AE37: 0 | AF37: 18.914 | AG37: 0 | AH37: 미/기/과탐 3% | AL37: 인하대 의예과 | AM37: 자연 | AN37: 100 | AO37: -511 | AP37: -511 | AQ37: 0 | AR37: 0.89 → 0.65 | BA37: 자연24
B38: 0.90 | C38: 1,953 | D38: -511 | F38: 98.59 | G38: 404.24 | H38: 409.66 | I38: 경북대 | J38: 의예과(정시지역) | K38: 자연 | L38: 6 | M38: 727.11 / | N38: 1000 | O38: 표점 | P38: 변표 | Q38: 2과목 | R38: 25 | S38: 38 | T38: 25 | U38: 98.59 | V38: 134.14766 | W38: 134.31433 | X38: 67.89 | Y38: 69.04 | Z38: 1등급 | AA38: 125 | AB38: 만점 | AC38: 10 | AD38: 만점 | AE38: 0 | AF38: 0 | AG38: 0 | AL38: 경북대 의예과(정시지역) | AM38: 자연 | AN38: 100 | AO38: -511 | AP38: -511 | AQ38: 0 | AR38: 0.90 → 0.67 | BA38: 자연25
B39: 0.97 | C39: 2,105 | D39: -511 | F39: 98.5 | G39: 403.77 | H39: 409.24 | I39: 연세대(미래) | J39: 의예과 | K39: 자연 | L39: 21 | M39: 721.75 / | N39: 1000 | O39: 표점 | P39: 변표 | Q39: 2과목 | R39: 22 | S39: 33 | T39: 33 | U39: 98.5 | V39: 134.00134 | W39: 134.16801 | X39: 67.8 | Y39: 68.44 | Z39: 1등급 | AA39: 111.11 | AB39: 만점 | AC39: 10 | AD39: 만점 | AE39: 0 | AF39: 0 | AG39: 0 | AL39: 연세대(미래) 의예과 | AM39: 자연 | AN39: 100 | AO39: -511 | AP39: -511 | AQ39: 0 | AR39: 0.98 → 0.74 | BA39: 자연26
B40: 0.97 | C40: 2,105 | D40: -520 | F40: 98.5 | G40: 403.76 | H40: 409.28 | I40: 가천대 | J40: 의예과 | K40: 자연 | L40: 40 | M40: 98.4 / | N40: 100 | O40: 백분위 | P40: 백분위 | Q40: 2과목 | R40: 25 | S40: 30 | T40: 25 | U40: 98.5 | V40: 134 | W40: 134.16667 | X40: 67.8 | Z40: 1등급 | AA40: 19.6 | AB40: 만점 | AC40: 0 | AD40: 만점 | AE40: 0 | AF40: 0 | AG40: 0 | AL40: 가천대 의예과 | AM40: 자연 | AN40: 100 | AO40: -520 | AP40: -520 | AQ40: 0 | AR40: 0.98 → 0.74 | BA40: 자연27
...

Sheet  본인점수 입력 
B1: 환산점수 엑셀배치표 2026학년도 수능 실채점기준 (2025. 12. 07 제작)
B2: 제작 및 검토 < 베텔기우스 > Betelgeuse058.tistory.com
AD3: 응시여부코드 | AE3: (1~2) | AF3: (3~5) | AG3: (6~13) | AI3: (10~13) | AJ3: (14~22) | AL3: 23 | AM3: 24 | AN3: 25
B4: 노란칸에 점수를 입력합니다. (영어, 한국사, 제2외국어 등 응시한 과목은 모두 입력해야 지원가능 여부를 알 수 있습니다.) (미응시 영역은 비워둠) | AE4: 적용점수
AE5: 고득점순 | AF5: 고득점순 | AG5: 고득점순 | AH5: 고득점순 | AI5: 가산점용 | AJ5: 고득점순 | AK5: 고득점순 | AL5: 고득점순 | AM5: 고득점순 | AN5: 고득점순
B6: 국어 | D6: 수학 | G6: 과탐 | O6: 사탐 | AE6: 1 | AF6: 1 | AG6: 1 | AH6: 2 | AI6: 1 | AJ6: 1 | AK6: 2 | AL6: 1 | AM6: 1 | AN6: 1
B7: 언매 | C7: 화작 | D7: 미적 | E7: 기하 | F7: 확통 | G7: 물리Ⅰ | H7: 화학Ⅰ | I7: 생명과학Ⅰ | J7: 지구과학Ⅰ | K7: 물리II | L7: 화학II | M7: 생명과학II | N7: 지구과학II | O7: 생활과윤리 | P7: 윤리와사상 | Q7: 한국지리 | R7: 세계지리 | S7: 동아시아사 | T7: 세계사 | U7: 경제 | V7: 정치와법 | W7: 사회문화 | AE7: 국어 | AF7: 수학 | AG7: 과탐1 | AH7: 과탐2 | AI7: 과탐Ⅱ | AJ7: 사탐1 | AK7: 사탐2 | AL7: 영어 | AM7: 한국사 | AN7: 제2외국어
A8: 원점수 | AD8: 원점 | AE8: =IFERROR(INDEX(B8:C8,MATCH($AE$6,B38:C38,0)),0) -> 0 | AF8: =IFERROR(INDEX(D8:F8,MATCH($AF$6,D38:F38,0)),0) -> 0 | AG8: =IFERROR(INDEX($G8:$N8,MATCH(AG$6,$G$38:$N$38,0)),0) -> 0 | AH8: =IFERROR(INDEX($G8:$N8,MATCH(AH$6,$G$38:$N$38,0)),0) -> 0 | AI8: =IFERROR(MAX(K8:N8),0) -> 0 | AJ8: =IFERROR(INDEX(O8:W8,MATCH($AJ$6,O38:W38,0)),0) -> 0 | AK8: =IFERROR(INDEX(O8:W8,MATCH($AK$6,O38:W38,0)),0) -> 0 | AL8: =B14 -> 0 | AM8: =C14 -> 0 | AN8: =D14 -> 0
A9: 표준점수 | B9: =IF($B$31=1,B22,IFERROR(ROUND(B58,0),"")) -> 0 | C9: =IF($B$31=1,C22,IFERROR(ROUND(C58,0),"")) -> 0 | D9: =IF($B$31=1,D22,IFERROR(ROUND(D58,0),"")) -> 0 | E9: =IF($B$31=1,E22,IFERROR(ROUND(E58,0),"")) -> 0 | F9: =IF($B$31=1,F22,IFERROR(ROUND(F58,0),"")) -> 0 | G9: =IF($B$31=1,G22,IFERROR(ROUND(G58,0),"")) -> 0 | H9: =IF($B$31=1,H22,IFERROR(ROUND(H58,0),"")) -> 0 | I9: =IF($B$31=1,I22,IFERROR(ROUND(I58,0),"")) -> 0 | ... W9: =IF($B$31=1,W22,IFERROR(ROUND(W58,0),"")) -> 0 | AD9: 표점 | AE9: =IFERROR(INDEX(B9:C9,MATCH($AE$6,B39:C39,0)),0) -> 0 | AF9: =IFERROR(INDEX(D9:F9,MATCH($AF$6,D39:F39,0)),0) -> 0 | AG9: =IFERROR(INDEX($G9:$N9,MATCH(AG$6,$G$39:$N$39,0)),0) -> 0 | AH9: =IFERROR(INDEX($G9:$N9,MATCH(AH$6,$G$39:$N$39,0)),0) -> 0 | AI9: =IFERROR(MAX(K9:N9),0) -> 0 | AJ9: =IFERROR(INDEX(O9:W9,MATCH($AJ$6,O39:W39,0)),0) -> 0 | AK9: =IFERROR(INDEX(O9:W9,MATCH($AK$6,O39:W39,0)),0) -> 0 | AL9: =B15 -> 0 | AM9: =C15 -> 0 | AN9: =D15 -> 0
A10: 백분위 | B10: =IF($B$31=1,B23,IF(B58="","",IFERROR(IF(MAX($B$163:$B$178)>110,INDEX($A$163:$A$253,MATCH(B$58,B163:B253,-1)),INDEX(B163:B253,MATCH(B$8,$A$163:$A$253,0))),""))) -> 0 | C10: =IF($B$31=1,C23,IF(C58="","",IFERROR(IF(MAX($B$163:$B$178)>110,INDEX($A$163:$A$253,MATCH(C$58,C163:C253,-1)),INDEX(C163:C253,MATCH(C$8,$A$163:$A$253,0))),""))) -> 0 | D10: =IF($B$31=1,D23,IF(D58="","",IFERROR(IF(MAX($B$163:$B$178)>110,INDEX($A$163:$A$253,MATCH(D$58,D163:D253,-1)),INDEX(D163:D253,MATCH(D$8,$A$163:$A$253,0))),""))) -> 0 | E10: =IF($B$31=1,E23,IF(E58="","",IFERROR(IF(MAX($B$163:$B$178)>110,INDEX($A$163:$A$253,MATCH(E$58,E163:E253,-1)),INDEX(E163:E253,MATCH(E$8,$A$163:$A$253,0))),""))) -> 0 | F10: =IF($B$31=1,F23,IF(F58="","",IFERROR(IF(MAX($B$163:$B$178)>110,INDEX($A$163:$A$253,MATCH(F$58,F163:F253,-1)),INDEX(F163:F253,MATCH(F$8,$A$163:$A$253,0))),""))) -> 0 | G10: =IF($B$31=1,G23,IF(G58="","",IFERROR(IF(MAX($B$163:$B$178)>110,INDEX($A$163:$A$253,MATCH(G$58,G163:G253,-1)),INDEX(G163:G253,MATCH(G$8,$AA$163:$AA$253,0))),""))) -> 0 | H10: =IF($B$31=1,H23,IF(H58="","",IFERROR(IF(MAX($B$163:$B$178)>110,INDEX($A$163:$A$253,MATCH(H$58,H163:H253,-1)),INDEX(H163:H253,MATCH(H$8,$AA$163:$AA$253,0))),""))) -> 0 | I10: =IF($B$31=1,I23,IF(I58="","",IFERROR(IF(MAX($B$163:$B$178)>110,INDEX($A$163:$A$253,MATCH(I$58,I163:I253,-1)),INDEX(I163:I253,MATCH(I$8,$AA$163:$AA$253,0))),""))) -> 0 | J10: =IF($B$31=1,J23,IF(J58="","",IFERROR(IF(MAX($B$163:$B$178)>110,INDEX($A$163:$A$253,MATCH(J$58,J163:J253,-1)),INDEX(J163:J253,MATCH(J$8,$AA$163:$AA$253,0))),""))) -> 0 | K10: =IF($B$31=1,K23,IF(K58="","",IFERROR(IF(MAX($B$163:$B$178)>110,INDEX($A$163:$A$253,MATCH(K$58,K163:K253,-1)),INDEX(K163:K253,MATCH(K$8,$AA$163:$AA$253,0))),""))) -> 0 | L10: =IF($B$31=1,L23,IF(L58="","",IFERROR(IF(MAX($B$163:$B$178)>110,INDEX($A$163:$A$253,MATCH(L$58,L163:L253,-1)),INDEX(L163:L253,MATCH(L$8,$AA$163:$AA$253,0))),""))) -> 0 | M10: =IF($B$31=1,M23,IF(M58="","",IFERROR(IF(MAX($B$163:$B$178)>110,INDEX($A$163:$A$253,MATCH(M$58,M163:M253,-1)),INDEX(M163:M253,MATCH(M$8,$AA$163:$AA$253,0))),""))) -> 0 | N10: =IF($B$31=1,N23,IF(N58="","",IFERROR(IF(MAX($B$163:$B$178)>110,INDEX($A$163:$A$253,MATCH(N$58,N163:N253,-1)),INDEX(N163:N253,MATCH(N$8,$AA$163:$AA$253,0))),""))) -> 0 | ... W10: =IF($B$31=1,W23,IF(W58="","",IFERROR(IF(MAX($B$163:$B$178)>110,INDEX($A$163:$A$253,MATCH(W$58,W163:W253,-1)),INDEX(W163:W253,MATCH(W$8,$AA$163:$AA$253,0))),""))) -> 0 | AD10: 백분 | AE10: =IFERROR(INDEX(B10:C10,MATCH($AE$6,B40:C40,0)),0) -> 0 | AF10: =IFERROR(INDEX(D10:F10,MATCH($AF$6,D40:F40,0)),0) -> 0 | AG10: =IFERROR(INDEX($G10:$N10,MATCH(AG$6,$G$40:$N$40,0)),0) -> 0 | AH10: =IFERROR(INDEX($G10:$N10,MATCH(AH$6,$G$40:$N$40,0)),0) -> 0 | AI10: =IFERROR(MAX(K10:N10),0) -> 0 | AJ10: =IFERROR(INDEX(O10:W10,MATCH($AJ$6,O40:W40,0)),0) -> 0 | AK10: =IFERROR(INDEX(O10:W10,MATCH($AK$6,O40:W40,0)),0) -> 0 | AL10: =B16 -> 0 | AM10: =C16 -> 0 | AN10: =D16 -> 0
A11: 등급 | B11: =IF($B$31=1,B24,IF(B8="","",IFERROR(INDEX(B263:B353,MATCH(B$8,$A$263:$A$353,0)),""))) -> 0 | C11: =IF($B$31=1,C24,IF(C8="","",IFERROR(INDEX(C263:C353,MATCH(C$8,$A$263:$A$353,0)),""))) -> 0 | D11: =IF($B$31=1,D24,IF(D8="","",IFERROR(INDEX(D263:D353,MATCH(D$8,$A$263:$A$353,0)),""))) -> 0 | E11: =IF($B$31=1,E24,IF(E8="","",IFERROR(INDEX(E263:E353,MATCH(E$8,$A$263:$A$353,0)),""))) -> 0 | F11: =IF($B$31=1,F24,IF(F8="","",IFERROR(INDEX(F263:F353,MATCH(F$8,$A$263:$A$353,0)),""))) -> 0 | G11: =IF($B$31=1,G24,IF(G8="","",IFERROR(INDEX(G263:G353,MATCH(G$8,$AA$263:$AA$353,0)),""))) -> 0 | H11: =IF($B$31=1,H24,IF(H8="","",IFERROR(INDEX(H263:H353,MATCH(H$8,$AA$263:$AA$353,0)),""))) -> 0 | I11: =IF($B$31=1,I24,IF(I8="","",IFERROR(INDEX(I263:I353,MATCH(I$8,$AA$263:$AA$353,0)),""))) -> 0 | J11: =IF($B$31=1,J24,IF(J8="","",IFERROR(INDEX(J263:J353,MATCH(J$8,$AA$263:$AA$353,0)),""))) -> 0 | K11: =IF($B$31=1,K24,IF(K8="","",IFERROR(INDEX(K263:K353,MATCH(K$8,$AA$263:$AA$353,0)),""))) -> 0 | L11: =IF($B$31=1,L24,IF(L8="","",IFERROR(INDEX(L263:L353,MATCH(L$8,$AA$263:$AA$353,0)),""))) -> 0 | M11: =IF($B$31=1,M24,IF(M8="","",IFERROR(INDEX(M263:M353,MATCH(M$8,$AA$263:$AA$353,0)),""))) -> 0 | N11: =IF($B$31=1,N24,IF(N8="","",IFERROR(INDEX(N263:N353,MATCH(N$8,$AA$263:$AA$353,0)),""))) -> 0 | ... W11: =IF($B$31=1,W24,IF(W8="","",IFERROR(INDEX(W263:W353,MATCH(W$8,$AA$263:$AA$353,0)),""))) -> 0 | AD11: 등급 | AE11: =IFERROR(INDEX(B11:C11,MATCH($AE$6,B41:C41,0)),0) -> 0 | AF11: =IFERROR(INDEX(D11:F11,MATCH($AF$6,D41:F41,0)),0) -> 0 | AG11: =IFERROR(INDEX($G11:$N11,MATCH(AG$6,$G$41:$N$41,0)),0) -> 0 | AH11: =IFERROR(INDEX($G11:$N11,MATCH(AH$6,$G$41:$N$41,0)),0) -> 0 | AI11: =IFERROR(MAX(K11:N11),0) -> 0 | AJ11: =IFERROR(INDEX(O11:W11,MATCH($AJ$6,O41:W41,0)),0) -> 0 | AK11: =IFERROR(INDEX(O11:W11,MATCH($AK$6,O41:W41,0)),0) -> 0 | AL11: =B17 | AM11: =C17 | AN11: =D17
B13: 영어 | C13: 한국사 | D13: 제2외국어
A14: 원점수
A15: 표준점수 | AD15: 과목수 | AG15: 8 | AH15: 8 | AI15: 4 | AJ15: 9 | AK15: 9
A16: 백분위 | AD16: 변표 | AE16: =IFERROR(INDEX(B21:C21,MATCH($AE$6,B42:C42,0)),0) -> 0 | AF16: =IFERROR(INDEX(D21:F21,MATCH($AF$6,D42:F42,0)),0) -> 0 | AG16: =IFERROR(INDEX($G21:$N21,MATCH(AG$6,$G$42:$N$42,0)),0) -> 0 | AH16: =IFERROR(INDEX($G21:$N21,MATCH(AH$6,$G$42:$N$42,0)),0) -> 0 | AI16: =IFERROR(MAX(K21:N21),0) -> 0 | AJ16: =IFERROR(INDEX(O21:W21,MATCH($AJ$6,O42:W42,0)),0) -> 0 | AK16: =IFERROR(INDEX(O21:W21,MATCH($AK$6,O42:W42,0)),0) -> 0 | AL16: =X21 -> 0 | AM16: =Y21 -> 0 | AN16: =Z21 -> 0
A17: 등급 | B17: =IF(AND($B31=1,B27>0),B27,IF(B14="","",IFERROR(INDEX(X263:X353,MATCH(B$14,$A$263:$A$333,0)),""))) | C17: =IF(AND($B31=1,C27>0),C27,IF(C14="","",IFERROR(INDEX(Y263:Y353,MATCH(C$14,$AA$263:$AA$333,0)),""))) | D17: =IF(AND($B31=1,D27>0),D27,IF(D14="","",IFERROR(INDEX(Z263:Z353,MATCH(D$14,$AA$263:$AA$333,0)),""))) | AD17: 최고표점 | AE17: =IFERROR(MAX(B32:C32),0) -> 139 | AF17: =IFERROR(MAX(D32:F32),0) -> 140 | AG17: =IFERROR(INDEX($G32:$N32,MATCH(AG$6,$G$39:$N$39,0)),0) -> 72 | AH17: =IFERROR(INDEX($G32:$N32,MATCH(AH$6,$G$39:$N$39,0)),0) -> 72 | AI17: =IFERROR(INDEX(K32:N32,MATCH(AI6,K39:N39,0)),0) -> 72 | AJ17: =IFERROR(INDEX(O32:W32,MATCH($AJ$6,O39:W39,0)),0) -> 69 | AK17: =IFERROR(INDEX(O32:W32,MATCH($AK$6,O39:W39,0)),0) -> 66 | AL17: =X22 -> 0 | AM17: =Y22 -> 0 | AN17: =Z22 -> 0
AD18: 응시과목명 | AG18: =IFERROR(INDEX($G7:$N7,MATCH(AG$6,$G$39:$N$39,0)),0) -> 지구과학II | AH18: =IFERROR(INDEX($G7:$N7,MATCH(AH$6,$G$39:$N$39,0)),0) -> 생명과학II | AI18: =IF(K43>0,K7,IF(L43>0,L7,IF(M43>0,M7,IF(N43>0,N7,"미응시")))) -> 미응시
AF19: 과탐 전체최고표점 | AG19: =LARGE(G32:N32,1) -> 73
B20: 국어 | D20: 수학 | G20: 과탐 | O20: 사탐 | AD20: 표점합 | AE20: =B22+C22+D22+F22+E22+G22+H22+I22+J22+K22+L22+M22+N22+O22+P22+Q22+R22+S22+T22+U22+V22+W22 -> 0
B21: 언매 | C21: 화작 | D21: 미적 | E21: 기하 | F21: 확통 | G21: 물리Ⅰ | H21: 화학Ⅰ | I21: 생명과학Ⅰ | J21: 지구과학Ⅰ | K21: 물리II | L21: 화학II | M21: 생명과학II | N21: 지구과학II | O21: 생활과윤리 | P21: 윤리와사상 | Q21: 한국지리 | R21: 세계지리 | S21: 동아시아사 | T21: 세계사 | U21: 경제 | V21: 정치와법 | W21: 사회문화 | AG21: 탐구 과목명(고득점순)
A22: 표준점수 | AD22: *원점일때 20~27행 축소 | AF22: =AD8 -> 원점 | AG22: =IF(AG8=0,"",OFFSET($G$7,0,AG28-1)) | AH22: =IF(AH8=0,"",OFFSET($G$7,0,AH28-1)) | AI22: =IF(AI8=0,"",OFFSET($K$7,0,AI28-1)) | AJ22: =IF(AJ8=0,"",OFFSET($O$7,0,AJ28-1)) | AK22: =IF(AK8=0,"",OFFSET($O$7,0,AK28-1))
A23: 백분위 | AD23: *표점일때 ad~an열은 축소 | AF23: =AD9 -> 표점 | AG23: =IF(AG9=0,"",OFFSET($G$7,0,AG29-1)) | AH23: =IF(AH9=0,"",OFFSET($G$7,0,AH29-1)) | AI23: =IF(AI9=0,"",OFFSET($K$7,0,AI29-1)) | AJ23: =IF(AJ9=0,"",OFFSET($O$7,0,AJ29-1)) | AK23: =IF(AK9=0,"",OFFSET($O$7,0,AK29-1))
A24: 등급 | AF24: =AD10 -> 백분 | AG24: =IF(AG10=0,"",OFFSET($G$7,0,AG30-1)) | AH24: =IF(AH10=0,"",OFFSET($G$7,0,AH30-1)) | AI24: =IF(AI10=0,"",OFFSET($K$7,0,AI30-1)) | AJ24: =IF(AJ10=0,"",OFFSET($O$7,0,AJ30-1)) | AK24: =IF(AK10=0,"",OFFSET($O$7,0,AK30-1))
AF25: =AD11 -> 등급 | AG25: =IF(AG11=0,"",OFFSET($G$7,0,AG31-1)) | AH25: =IF(AH11=0,"",OFFSET($G$7,0,AH31-1)) | AI25: =IF(AI11=0,"",OFFSET($K$7,0,AI31-1)) | AJ25: =IF(AJ11=0,"",OFFSET($O$7,0,AJ31-1)) | AK25: =IF(AK11=0,"",OFFSET($O$7,0,AK31-1))
B26: 영어 | C26: 한국사 | D26: 제2외국어 | AF26: =AD12 -> 0 | AG26: =IF(AG12=0,"",OFFSET($G$7,0,AG32-1)) | AH26: =IF(AH12=0,"",OFFSET($G$7,0,AH32-1)) | AI26: =IF(AI12=0,"",OFFSET($K$7,0,AI32-1)) | AJ26: =IF(AJ12=0,"",OFFSET($O$7,0,AJ32-1)) | AK26: =IF(AK12=0,"",OFFSET($O$7,0,AK32-1))
A27: 등급 | AF27: =AD13 -> 0 | AG27: =IF(AG13=0,"",OFFSET($G$7,0,AG33-1)) | AH27: =IF(AH13=0,"",OFFSET($G$7,0,AH33-1)) | AI27: =IF(AI13=0,"",OFFSET($K$7,0,AI33-1)) | AJ27: =IF(AJ13=0,"",OFFSET($O$7,0,AJ33-1)) | AK27: =IF(AK13=0,"",OFFSET($O$7,0,AK33-1))
AF28: =AF22 -> 원점 | AG28: =MATCH(AG8,$G8:$N8,0) -> #N/A | AH28: =IF(AH8<>AG8,MATCH(AH8,$G8:$N8,0),AG28+MATCH(AH8,OFFSET($G8,0,AG28,1,AH$15-AG28),0)) -> #N/A | AI28: =MATCH(AI8,$K8:$N8,0) -> #N/A | AJ28: =MATCH(AJ8,$O8:$W8,0) -> #N/A | AK28: =IF(AK8<>AJ8,MATCH(AK8,$O8:$W8,0),AJ28+MATCH(AK8,OFFSET($O8,0,AJ28,1,AK$15-AJ28),0)) -> #N/A
AF29: =AF23 -> 표점 | AG29: =MATCH(AG9,$G9:$N9,0) -> 1 | AH29: =IF(AH9<>AG9,MATCH(AH9,$G9:$N9,0),AG29+MATCH(AH9,OFFSET($G9,0,AG29,1,AH$15-AG29),0)) -> 2 | AI29: =MATCH(AI9,$K9:$N9,0) -> 1 | AJ29: =MATCH(AJ9,$O9:$W9,0) -> 1 | AK29: =IF(AK9<>AJ9,MATCH(AK9,$O9:$W9,0),AJ29+MATCH(AK9,OFFSET($O9,0,AJ29,1,AK$15-AJ29),0)) -> 2
AF30: =AF24 -> 백분 | AG30: =MATCH(AG10,$G10:$N10,0) -> 1 | AH30: =IF(AH10<>AG10,MATCH(AH10,$G10:$N10,0),AG30+MATCH(AH10,OFFSET($G10,0,AG30,1,AH$15-AG30),0)) -> 2 | AI30: =MATCH(AI10,$K10:$N10,0) -> 1 | AJ30: =MATCH(AJ10,$O10:$W10,0) -> 1 | AK30: =IF(AK10<>AJ10,MATCH(AK10,$O10:$W10,0),AJ30+MATCH(AK10,OFFSET($O10,0,AJ30,1,AK$15-AJ30),0)) -> 2
A31: 원점/표점코드 | B31: ='배치점수 계산기'!E4 -> 1 | C31: ='배치점수 계산기'!D5 -> 표준점수 기준 | E31: *코드는 배치점수 계산기의 값을 따름 | X31: 영어 | Y31: 한국사 | Z31: 제2외국 | AF31: =AF25 -> 등급 | AG31: =MATCH(AG11,$G11:$N11,0) -> 1 | AH31: =IF(AH11<>AG11,MATCH(AH11,$G11:$N11,0),AG31+MATCH(AH11,OFFSET($G11,0,AG31,1,AH$15-AG31),0)) -> 2 | AI31: =MATCH(AI11,$K11:$N11,0) -> 1 | AJ31: =MATCH(AJ11,$O11:$W11,0) -> 1 | AK31: =IF(AK11<>AJ11,MATCH(AK11,$O11:$W11,0),AJ31+MATCH(AK11,OFFSET($O11,0,AJ31,1,AK$15-AJ31),0)) -> 2
A32: 최고표점 | B32: =IFERROR(IF($B$31=1,B49,ROUND(B63,0)),"") -> 139 | C32: =IFERROR(IF($B$31=1,C49,ROUND(C63,0)),"") -> 139 | D32: =IFERROR(IF($B$31=1,D49,ROUND(D63,0)),"") -> 140 | E32: =IFERROR(IF($B$31=1,E49,ROUND(E63,0)),"") -> 137 | F32: =IFERROR(IF($B$31=1,F49,ROUND(F63,0)),"") -> 134 | G32: =IFERROR(IF($B$31=1,G49,ROUND(G63,0)),"") -> 67 | H32: =IFERROR(IF($B$31=1,H49,ROUND(H63,0)),"") -> 65 | I32: =IFERROR(IF($B$31=1,I49,ROUND(I63,0)),"") -> 70 | ... W32: =IFERROR(IF($B$31=1,W49,ROUND(W63,0)),"") -> 69 | X32: =IFERROR(X63,"") -> 0 | Y32: =IFERROR(Y63,"") -> 0 | Z32: =IFERROR(Z63,"") -> 0 | AF32: =AF26 -> 0 | AG32: =MATCH(AG12,$G12:$N12,0) -> #N/A | AH32: =IF(AH12<>AG12,MATCH(AH12,$G12:$N12,0),AG32+MATCH(AH12,OFFSET($G12,0,AG32,1,AH$15-AG32),0)) -> #N/A | AI32: =MATCH(AI12,$K12:$N12,0) -> #N/A | AJ32: =MATCH(AJ12,$O12:$W12,0) -> #N/A | AK32: =IF(AK12<>AJ12,MATCH(AK12,$O12:$W12,0),AJ32+MATCH(AK12,OFFSET($O12,0,AJ32,1,AK$15-AJ32),0)) -> #N/A
A33: 원점순위용 | B33: =IF(B8="","",B8+COLUMN(B8)*0.0001) | C33: =IF(C8="","",C8+COLUMN(C8)*0.0001) | D33: =IF(D8="","",D8+COLUMN(D8)*0.0001) | E33: =IF(E8="","",E8+COLUMN(E8)*0.0001) | F33: =IF(F8="","",F8+COLUMN(F8)*0.0001) | G33: =IF(G8="","",G8+COLUMN(G8)*0.0001) | H33: =IF(H8="","",H8+COLUMN(H8)*0.0001) | I33: =IF(I8="","",I8+COLUMN(I8)*0.0001) | ... W33: =IF(W8="","",W8+COLUMN(W8)*0.0001)
A34: 표점순위용 | B34: =IFERROR(IF($B$31=9,B9+COLUMN(B9)*0.0001,B22+COLUMN(B22)*0.0001),"") -> 0.0002 | C34: =IFERROR(IF($B$31=9,C9+COLUMN(C9)*0.0001,C22+COLUMN(C22)*0.0001),"") -> 0.0003 | D34: =IFERROR(IF($B$31=9,D9+COLUMN(D9)*0.0001,D22+COLUMN(D22)*0.0001),"") -> 0.0004 | E34: =IFERROR(IF($B$31=9,E9+COLUMN(E9)*0.0001,E22+COLUMN(E22)*0.0001),"") -> 0.0005 | F34: =IFERROR(IF($B$31=9,F9+COLUMN(F9)*0.0001,F22+COLUMN(F22)*0.0001),"") -> 0.0006 | G34: =IFERROR(IF($B$31=9,G9+COLUMN(G9)*0.0001,G22+COLUMN(G22)*0.0001),"") -> 0.0007 | H34: =IFERROR(IF($B$31=9,H9+COLUMN(H9)*0.0001,H22+COLUMN(H22)*0.0001),"") -> 0.0008 | I34: =IFERROR(IF($B$31=9,I9+COLUMN(I9)*0.0001,I22+COLUMN(I22)*0.0001),"") -> 0.0009 | ... W34: =IFERROR(IF($B$31=9,W9+COLUMN(W9)*0.0001,W22+COLUMN(W22)*0.0001),"") -> 0.0023
A35: 백분순위용 | B35: =IFERROR(IF($B$31=9,B10+COLUMN(B10)*0.0001,B23+COLUMN(B23)*0.0001),"") -> 0.0002 | C35: =IFERROR(IF($B$31=9,C10+COLUMN(C10)*0.0001,C23+COLUMN(C23)*0.0001),"") -> 0.0003 | D35: =IFERROR(IF($B$31=9,D10+COLUMN(D10)*0.0001,D23+COLUMN(D23)*0.0001),"") -> 0.0004 | E35: =IFERROR(IF($B$31=9,E10+COLUMN(E10)*0.0001,E23+COLUMN(E23)*0.0001),"") -> 0.0005 | F35: =IFERROR(IF($B$31=9,F10+COLUMN(F10)*0.0001,F23+COLUMN(F23)*0.0001),"") -> 0.0006 | G35: =IFERROR(IF($B$31=9,G10+COLUMN(G10)*0.0001,G23+COLUMN(G23)*0.0001),"") -> 0.0007 | H35: =IFERROR(IF($B$31=9,H10+COLUMN(H10)*0.0001,H23+COLUMN(H23)*0.0001),"") -> 0.0008 | I35: =IFERROR(IF($B$31=9,I10+COLUMN(I10)*0.0001,I23+COLUMN(I23)*0.0001),"") -> 0.0009 | ... W35: =IFERROR(IF($B$31=9,W10+COLUMN(W10)*0.0001,W23+COLUMN(W23)*0.0001),"") -> 0.0023
A36: 등급순위용 | B36: =IFERROR(IF($B$31=9,B11+COLUMN(B11)*0.0001,B24+COLUMN(B24)*0.0001),"") -> 0.0002 | C36: =IFERROR(IF($B$31=9,C11+COLUMN(C11)*0.0001,C24+COLUMN(C24)*0.0001),"") -> 0.0003 | D36: =IFERROR(IF($B$31=9,D11+COLUMN(D11)*0.0001,D24+COLUMN(D24)*0.0001),"") -> 0.0004 | E36: =IFERROR(IF($B$31=9,E11+COLUMN(E11)*0.0001,E24+COLUMN(E24)*0.0001),"") -> 0.0005 | F36: =IFERROR(IF($B$31=9,F11+COLUMN(F11)*0.0001,F24+COLUMN(F24)*0.0001),"") -> 0.0006 | G36: =IFERROR(IF($B$31=9,G11+COLUMN(G11)*0.0001,G24+COLUMN(G24)*0.0001),"") -> 0.0007 | H36: =IFERROR(IF($B$31=9,H11+COLUMN(H11)*0.0001,H24+COLUMN(H24)*0.0001),"") -> 0.0008 | I36: =IFERROR(IF($B$31=9,I11+COLUMN(I11)*0.0001,I24+COLUMN(I24)*0.0001),"") -> 0.0009 | ... W36: =IFERROR(IF($B$31=9,W11+COLUMN(W11)*0.0001,W24+COLUMN(W24)*0.0001),"") -> 0.0023 | X36: =IF($B$31=9,B17+COLUMN(B17)*0.0001,B27+COLUMN(B27)*0.0001) -> 0.0002 | Y36: =IF($B$31=9,C17+COLUMN(C17)*0.0001,C27+COLUMN(C27)*0.0001) -> 0.0003 | Z36: =IF($B$31=9,D17+COLUMN(D17)*0.0001,D27+COLUMN(D27)*0.0001) -> 0.0004
A38: 원점순위 | B38: =IFERROR(RANK(B33,$B33:$C33,0),"") | C38: =IFERROR(RANK(C33,$B33:$C33,0),"") | D38: =IFERROR(RANK(D33,$D33:$F33,0),"") | E38: =IFERROR(RANK(E33,$D33:$F33,0),"") | F38: =IFERROR(RANK(F33,$D33:$F33,0),"") | G38: =IFERROR(RANK(G33,$G33:$N33,0),"") | H38: =IFERROR(RANK(H33,$G33:$N33,0),"") | I38: =IFERROR(RANK(I33,$G33:$N33,0),"") | J38: =IFERROR(RANK(J33,$G33:$N33,0),"") | K38: =IFERROR(RANK(K33,$G33:$N33,0),"") | L38: =IFERROR(RANK(L33,$G33:$N33,0),"") | M38: =IFERROR(RANK(M33,$G33:$N33,0),"") | N38: =IFERROR(RANK(N33,$G33:$N33,0),"") | O38: =IFERROR(RANK(O33,$O33:$W33,0),"") | P38: =IFERROR(RANK(P33,$O33:$W33,0),"") | Q38: =IFERROR(RANK(Q33,$O33:$W33,0),"") | R38: =IFERROR(RANK(R33,$O33:$W33,0),"") | S38: =IFERROR(RANK(S33,$O33:$W33,0),"") | T38: =IFERROR(RANK(T33,$O33:$W33,0),"") | U38: =IFERROR(RANK(U33,$O33:$W33,0),"") | V38: =IFERROR(RANK(V33,$O33:$W33,0),"") | W38: =IFERROR(RANK(W33,$O33:$W33,0),"")
A39: 표점순위 | B39: =IFERROR(RANK(B34,$B34:$C34,0),"") -> 2 | C39: =IFERROR(RANK(C34,$B34:$C34,0),"") -> 1 | D39: =IFERROR(RANK(D34,$D34:$F34,0),"") -> 3 | E39: =IFERROR(RANK(E34,$D34:$F34,0),"") -> 2 | F39: =IFERROR(RANK(F34,$D34:$F34,0),"") -> 1 | G39: =IFERROR(RANK(G34,$G34:$N34,0),"") -> 8 | H39: =IFERROR(RANK(H34,$G34:$N34,0),"") -> 7 | I39: =IFERROR(RANK(I34,$G34:$N34,0),"") -> 6 | J39: =IFERROR(RANK(J34,$G34:$N34,0),"") -> 5 | K39: =IFERROR(RANK(K34,$G34:$N34,0),"") -> 4 | L39: =IFERROR(RANK(L34,$G34:$N34,0),"") -> 3 | M39: =IFERROR(RANK(M34,$G34:$N34,0),"") -> 2 | N39: =IFERROR(RANK(N34,$G34:$N34,0),"") -> 1 | O39: =IFERROR(RANK(O34,$O34:$W34,0),"") -> 9 | P39: =IFERROR(RANK(P34,$O34:$W34,0),"") -> 8 | Q39: =IFERROR(RANK(Q34,$O34:$W34,0),"") -> 7 | R39: =IFERROR(RANK(R34,$O34:$W34,0),"") -> 6 | S39: =IFERROR(RANK(S34,$O34:$W34,0),"") -> 5 | T39: =IFERROR(RANK(T34,$O34:$W34,0),"") -> 4 | U39: =IFERROR(RANK(U34,$O34:$W34,0),"") -> 3 | V39: =IFERROR(RANK(V34,$O34:$W34,0),"") -> 2 | W39: =IFERROR(RANK(W34,$O34:$W34,0),"") -> 1
A40: 백분순위 | B40: =IFERROR(RANK(B35,$B35:$C35,0),"") -> 2 | C40: =IFERROR(RANK(C35,$B35:$C35,0),"") -> 1 | D40: =IFERROR(RANK(D35,$D35:$F35,0),"") -> 3 | E40: =IFERROR(RANK(E35,$D35:$F35,0),"") -> 2 | F40: =IFERROR(RANK(F35,$D35:$F35,0),"") -> 1 | G40: =IFERROR(RANK(G35,$G35:$N35,0),"") -> 8 | H40: =IFERROR(RANK(H35,$G35:$N35,0),"") -> 7 | I40: =IFERROR(RANK(I35,$G35:$N35,0),"") -> 6 | J40: =IFERROR(RANK(J35,$G35:$N35,0),"") -> 5 | K40: =IFERROR(RANK(K35,$G35:$N35,0),"") -> 4 | L40: =IFERROR(RANK(L35,$G35:$N35,0),"") -> 3 | M40: =IFERROR(RANK(M35,$G35:$N35,0),"") -> 2 | N40: =IFERROR(RANK(N35,$G35:$N35,0),"") -> 1 | O40: =IFERROR(RANK(O35,$O35:$W35,0),"") -> 9 | P40: =IFERROR(RANK(P35,$O35:$W35,0),"") -> 8 | Q40: =IFERROR(RANK(Q35,$O35:$W35,0),"") -> 7 | R40: =IFERROR(RANK(R35,$O35:$W35,0),"") -> 6 | S40: =IFERROR(RANK(S35,$O35:$W35,0),"") -> 5 | T40: =IFERROR(RANK(T35,$O35:$W35,0),"") -> 4 | U40: =IFERROR(RANK(U35,$O35:$W35,0),"") -> 3 | V40: =IFERROR(RANK(V35,$O35:$W35,0),"") -> 2 | W40: =IFERROR(RANK(W35,$O35:$W35,0),"") -> 1
A41: 등급순위 | B41: =IFERROR(RANK(B36,$B36:$C36,0),"") -> 2 | C41: =IFERROR(RANK(C36,$B36:$C36,0),"") -> 1 | D41: =IFERROR(RANK(D36,$D36:$F36,0),"") -> 3 | E41: =IFERROR(RANK(E36,$D36:$F36,0),"") -> 2 | F41: =IFERROR(RANK(F36,$D36:$F36,0),"") -> 1 | G41: =IFERROR(RANK(G36,$G36:$N36,0),"") -> 8 | H41: =IFERROR(RANK(H36,$G36:$N36,0),"") -> 7 | I41: =IFERROR(RANK(I36,$G36:$N36,0),"") -> 6 | J41: =IFERROR(RANK(J36,$G36:$N36,0),"") -> 5 | K41: =IFERROR(RANK(K36,$G36:$N36,0),"") -> 4 | L41: =IFERROR(RANK(L36,$G36:$N36,0),"") -> 3 | M41: =IFERROR(RANK(M36,$G36:$N36,0),"") -> 2 | N41: =IFERROR(RANK(N36,$G36:$N36,0),"") -> 1 | O41: =IFERROR(RANK(O36,$O36:$W36,0),"") -> 9 | P41: =IFERROR(RANK(P36,$O36:$W36,0),"") -> 8 | Q41: =IFERROR(RANK(Q36,$O36:$W36,0),"") -> 7 | R41: =IFERROR(RANK(R36,$O36:$W36,0),"") -> 6 | S41: =IFERROR(RANK(S36,$O36:$W36,0),"") -> 5 | T41: =IFERROR(RANK(T36,$O36:$W36,0),"") -> 4 | U41: =IFERROR(RANK(U36,$O36:$W36,0),"") -> 3 | V41: =IFERROR(RANK(V36,$O36:$W36,0),"") -> 2 | W41: =IFERROR(RANK(W36,$O36:$W36,0),"") -> 1
A43: 응시여부 | B43: =IF(OR(B8>0,AND(B22>0,B23>0)),1,0) -> 0 | C43: =IF(OR(C8>0,AND(C22>0,C23>0)),1,0) -> 0 | D43: =IF(OR(D8>0,AND(D22>0,D23>0)),1,0) -> 0 | E43: =IF(OR(E8>0,AND(E22>0,E23>0)),1,0) -> 0 | F43: =IF(OR(F8>0,AND(F22>0,F23>0)),1,0) -> 0 | G43: =IF(OR(G8>0,AND(G22>0,G23>0)),1,0) -> 0 | H43: =IF(OR(H8>0,AND(H22>0,H23>0)),1,0) -> 0 | I43: =IF(OR(I8>0,AND(I22>0,I23>0)),1,0) -> 0 | ... W43: =IF(OR(W8>0,AND(W22>0,W23>0)),1,0) -> 0 | X43: =IF(OR(B14>0,AND(B27>0,B27>0)),1,0) -> 0 | Y43: =IF(OR(C14>0,AND(C27>0,C27>0)),1,0) -> 0 | Z43: =IF(OR(D14>0,AND(D27>0,D27>0)),1,0) -> 0
...

Sheet        가 군       
B1: 가 | C1: 나 | D1: 다 | E1: 가나다 | I1: 환산점수 배치표 (가 군) 2026학년도 수능 실채점기준
B2: 1 | C2: 2 | D2: 3 | E2: 4 | R2: 제작 및 검토 <베텔기우스> Betelgeuse058.tistory.com
B3: 군 입력
B4: 1 | C4: =IF($B$4=1,CONCATENATE($B$1,AE4),IF($B$4=2,CONCATENATE($C$1,AE4),IF($B$4=3,CONCATENATE($D$1,AE4),IF($B$4=4,CONCATENATE($E$1,AE4))))) -> 가
C5: =IFERROR(INDEX('배치점수 계산기'!A9:C9,MATCH(C4,'배치점수 계산기'!A7:C7,0)),) -> 0 | R5: 판정 기준점수
M6: 감점 상세 | P6: 나의 점수 | R6: 안정 | S6: 적정 | T6: 예상컷 | U6: 도전 | W6: 반영 방법 | Y6: 실질 반영비
E7: 공식 연번 | H7: 모집군 | I7: 대학 | J7: 학과 | K7: 계열 | L7: 지원가능 | M7: 영어감점 | N7: 영어감점 비율 | O7: 한국사/외국어 | P7: 합격확률 추정 | Q7: 환산점수 | R7: 0.9 | S7: 0.7 | T7: 0.4 | U7: 0.1 | V7: 0.03 | W7: 국 수 | X7: 탐구 | Y7: 국 | Z7: 수 | AA7: 탐 | AD7: 서식기준
C8: =_xlfn.CONCAT($C$4,G8) -> 가1 | D8: =MATCH($C8,'배치점수 계산기'!$O$11:$O$3001,0) -> 1 | E8: =OFFSET('배치점수 계산기'!A$10,D8,0) -> 5 | F8: =MATCH(E8,환산공식!$C$16:$C$903,0) -> 5 | G8: 1 | H8: =IFERROR(INDEX('배치점수 계산기'!C$11:C$3001,MATCH($C8,'배치점수 계산기'!$O$11:$O$3001,0)),"") -> 가 | I8: =IFERROR(INDEX('배치점수 계산기'!D$11:D$3001,MATCH($C8,'배치점수 계산기'!$O$11:$O$3001,0)),"") -> 연세대 | J8: =IFERROR(INDEX('배치점수 계산기'!E$11:E$3001,MATCH($C8,'배치점수 계산기'!$O$11:$O$3001,0)),"") -> 시스템반도체공학과 | K8: =IFERROR(INDEX('배치점수 계산기'!F$11:F$3001,MATCH($C8,'배치점수 계산기'!$O$11:$O$3001,0)),"") -> 자연 | L8: =IF(OFFSET(환산공식!$ED$15,$F8,0)=1,"O","X") -> X | M8: =IFERROR(OFFSET(환산공식!DJ$15,$F8,0),"") -> 105.6 | N8: =IFERROR(CONCATENATE(ROUND(OFFSET(환산공식!DK$15,$F8,0),1),"%"),"") -> 100% | O8: =IFERROR(OFFSET(환산공식!DL$15,$F8,0),"") -> 0 | P8: =IF(E8="","",IF(Q8>R8,"90% 이상",IF(Q8>S8,CONCATENATE(ROUND(((Q8-S8)/(R8-S8))*20+70,0),"%"),IF(Q8>T8,CONCATENATE(ROUND(((Q8-T8)/(S8-T8))*30+40,0),"%"),IF(Q8>U8,CONCATENATE(ROUND(((Q8-U8)/(T8-U8))*30+10,0),"%"),IF(Q8>V8,CONCATENATE(ROUND(((Q8-V8)/(U8-V8))*7+3,0),"%"),"3% 이하")))))) -> 3% 이하 | Q8: =IFERROR(ROUND(OFFSET(환산공식!$FG$15,$F8,0),3),"") -> 0 | R8: =OFFSET('배치점수 계산기'!H$10,$D8,0) -> 670.259 | S8: =OFFSET('배치점수 계산기'!I$10,$D8,0) -> 669.463 | T8: =OFFSET('배치점수 계산기'!J$10,$D8,0) -> 668.39 | U8: =OFFSET('배치점수 계산기'!K$10,$D8,0) -> 663.419 | V8: =OFFSET('배치점수 계산기'!L$10,$D8,0) -> 657.803 | W8: =OFFSET('배치점수 계산기'!M$10,$D8,0) -> 표점 | X8: =OFFSET('배치점수 계산기'!N$10,$D8,0) -> 변표 | Y8: =OFFSET(환산공식!FW$15,$F8,0) -> 0.25 | Z8: =OFFSET(환산공식!FX$15,$F8,0) -> 0.38 | AA8: =OFFSET(환산공식!FY$15,$F8,0) -> 0.38 | AD8: =IF(L8="X",6,IF(Q8>R8,1,IF(Q8>S8,2,IF(Q8>T8,3,IF(Q8>U8,4,IF(Q8>=V8,5,IF(Q8<V8,6,""))))))) -> 6
C9: 가2 | D9: 2 | E9: 5 | F9: 5 | G9: 2 | H9: 가 | I9: 연세대 | J9: 전기전자공학부 | K9: 자연 | L9: =IF(OFFSET(환산공식!$ED$15,$F9,0)=1,"O","X") -> X | M9: =IFERROR(OFFSET(환산공식!DJ$15,$F9,0),"") -> 105.6 | N9: =IFERROR(CONCATENATE(ROUND(OFFSET(환산공식!DK$15,$F9,0),1),"%"),"") -> 100% | O9: =IFERROR(OFFSET(환산공식!DL$15,$F9,0),"") -> 0 | P9: =IF(E9="","",IF(Q9>R9,"90% 이상",IF(Q9>S9,CONCATENATE(ROUND(((Q9-S9)/(R9-S9))*20+70,0),"%"),IF(Q9>T9,CONCATENATE(ROUND(((Q9-T9)/(S9-T9))*30+40,0),"%"),IF(Q9>U9,CONCATENATE(ROUND(((Q9-U9)/(T9-U9))*30+10,0),"%"),IF(Q9>V9,CONCATENATE(ROUND(((Q9-V9)/(U9-V9))*7+3,0),"%"),"3% 이하")))))) -> 3% 이하 | Q9: =IFERROR(ROUND(OFFSET(환산공식!$FG$15,$F9,0),3),"") -> 0 | R9: =OFFSET('배치점수 계산기'!H$10,$D9,0) -> 665.026 | S9: =OFFSET('배치점수 계산기'!I$10,$D9,0) -> 664.514 | T9: =OFFSET('배치점수 계산기'!J$10,$D9,0) -> 662.35 | U9: =OFFSET('배치점수 계산기'!K$10,$D9,0) -> 661.072 | V9: =OFFSET('배치점수 계산기'!L$10,$D9,0) -> 656.12 | W9: =OFFSET('배치점수 계산기'!M$10,$D9,0) -> 표점 | X9: =OFFSET('배치점수 계산기'!N$10,$D9,0) -> 변표 | Y9: =OFFSET(환산공식!FW$15,$F9,0) -> 0.25 | Z9: =OFFSET(환산공식!FX$15,$F9,0) -> 0.38 | AA9: =OFFSET(환산공식!FY$15,$F9,0) -> 0.38 | AD9: =IF(L9="X",6,IF(Q9>R9,1,IF(Q9>S9,2,IF(Q9>T9,3,IF(Q9>U9,4,IF(Q9>=V9,5,IF(Q9<V9,6,""))))))) -> 6
C10: 가3 | D10: 3 | E10: 5 | F10: 5 | G10: 3 | H10: 가 | I10: 연세대 | J10: 첨단컴퓨팅학부 | K10: 자연 | L10: =IF(OFFSET(환산공식!$ED$15,$F10,0)=1,"O","X") -> X | M10: =IFERROR(OFFSET(환산공식!DJ$15,$F10,0),"") -> 105.6 | N10: =IFERROR(CONCATENATE(ROUND(OFFSET(환산공식!DK$15,$F10,0),1),"%"),"") -> 100% | O10: =IFERROR(OFFSET(환산공식!DL$15,$F10,0),"") -> 0 | P10: =IF(E10="","",IF(Q10>R10,"90% 이상",IF(Q10>S10,CONCATENATE(ROUND(((Q10-S10)/(R10-S10))*20+70,0),"%"),IF(Q10>T10,CONCATENATE(ROUND(((Q10-T10)/(S10-T10))*30+40,0),"%"),IF(Q10>U10,CONCATENATE(ROUND(((Q10-U10)/(T10-U10))*30+10,0),"%"),IF(Q10>V10,CONCATENATE(ROUND(((Q10-V10)/(U10-V10))*7+3,0),"%"),"3% 이하")))))) -> 3% 이하 | Q10: =IFERROR(ROUND(OFFSET(환산공식!$FG$15,$F10,0),3),"") -> 0 | R10: =OFFSET('배치점수 계산기'!H$10,$D10,0) -> 666.6 | S10: =OFFSET('배치점수 계산기'!I$10,$D10,0) -> 665.026 | T10: =OFFSET('배치점수 계산기'!J$10,$D10,0) -> 661.688 | U10: =OFFSET('배치점수 계산기'!K$10,$D10,0) -> 657.592 | V10: =OFFSET('배치점수 계산기'!L$10,$D10,0) -> 654.384 | W10: =OFFSET('배치점수 계산기'!M$10,$D10,0) -> 표점 | X10: =OFFSET('배치점수 계산기'!N$10,$D10,0) -> 변표 | Y10: =OFFSET(환산공식!FW$15,$F10,0) -> 0.25 | Z10: =OFFSET(환산공식!FX$15,$F10,0) -> 0.38 | AA10: =OFFSET(환산공식!FY$15,$F10,0) -> 0.38 | AD10: =IF(L10="X",6,IF(Q10>R10,1,IF(Q10>S10,2,IF(Q10>T10,3,IF(Q10>U10,4,IF(Q10>=V10,5,IF(Q10<V10,6,""))))))) -> 6
C11: 가4 | D11: 4 | E11: 5 | F11: 5 | G11: 4 | H11: 가 | I11: 연세대 | J11: 기계공학부 | K11: 자연 | L11: =IF(OFFSET(환산공식!$ED$15,$F11,0)=1,"O","X") -> X | M11: =IFERROR(OFFSET(환산공식!DJ$15,$F11,0),"") -> 105.6 | N11: =IFERROR(CONCATENATE(ROUND(OFFSET(환산공식!DK$15,$F11,0),1),"%"),"") -> 100% | O11: =IFERROR(OFFSET(환산공식!DL$15,$F11,0),"") -> 0 | P11: =IF(E11="","",IF(Q11>R11,"90% 이상",IF(Q11>S11,CONCATENATE(ROUND(((Q11-S11)/(R11-S11))*20+70,0),"%"),IF(Q11>T11,CONCATENATE(ROUND(((Q11-T11)/(S11-T11))*30+40,0),"%"),IF(Q11>U11,CONCATENATE(ROUND(((Q11-U11)/(T11-U11))*30+10,0),"%"),IF(Q11>V11,CONCATENATE(ROUND(((Q11-V11)/(U11-V11))*7+3,0),"%"),"3% 이하")))))) -> 3% 이하 | Q11: =IFERROR(ROUND(OFFSET(환산공식!$FG$15,$F11,0),3),"") -> 0 | R11: =OFFSET('배치점수 계산기'!H$10,$D11,0) -> 663.82 | S11: =OFFSET('배치점수 계산기'!I$10,$D11,0) -> 663.169 | T11: =OFFSET('배치점수 계산기'!J$10,$D11,0) -> 661.688 | U11: =OFFSET('배치점수 계산기'!K$10,$D11,0) -> 660.147 | V11: =OFFSET('배치점수 계산기'!L$10,$D11,0) -> 657.027 | W11: =OFFSET('배치점수 계산기'!M$10,$D11,0) -> 표점 | X11: =OFFSET('배치점수 계산기'!N$10,$D11,0) -> 변표 | Y11: =OFFSET(환산공식!FW$15,$F11,0) -> 0.25 | Z11: =OFFSET(환산공식!FX$15,$F11,0) -> 0.38 | AA11: =OFFSET(환산공식!FY$15,$F11,0) -> 0.38 | AD11: =IF(L11="X",6,IF(Q11>R11,1,IF(Q11>S11,2,IF(Q11>T11,3,IF(Q11>U11,4,IF(Q11>=V11,5,IF(Q11<V11,6,""))))))) -> 6
C12: 가5 | D12: 5 | E12: 5 | F12: 5 | G12: 5 | H12: 가 | I12: 연세대 | J12: 신소재공학부 | K12: 자연 | L12: =IF(OFFSET(환산공식!$ED$15,$F12,0)=1,"O","X") -> X | M12: =IFERROR(OFFSET(환산공식!DJ$15,$F12,0),"") -> 105.6 | N12: =IFERROR(CONCATENATE(ROUND(OFFSET(환산공식!DK$15,$F12,0),1),"%"),"") -> 100% | O12: =IFERROR(OFFSET(환산공식!DL$15,$F12,0),"") -> 0 | P12: =IF(E12="","",IF(Q12>R12,"90% 이상",IF(Q12>S12,CONCATENATE(ROUND(((Q12-S12)/(R12-S12))*20+70,0),"%"),IF(Q12>T12,CONCATENATE(ROUND(((Q12-T12)/(S12-T12))*30+40,0),"%"),IF(Q12>U12,CONCATENATE(ROUND(((Q12-U12)/(T12-U12))*30+10,0),"%"),IF(Q12>V12,CONCATENATE(ROUND(((Q12-V12)/(U12-V12))*7+3,0),"%"),"3% 이하")))))) -> 3% 이하 | Q12: =IFERROR(ROUND(OFFSET(환산공식!$FG$15,$F12,0),3),"") -> 0 | R12: =OFFSET('배치점수 계산기'!H$10,$D12,0) -> 663.419 | S12: =OFFSET('배치점수 계산기'!I$10,$D12,0) -> 663.169 | T12: =OFFSET('배치점수 계산기'!J$10,$D12,0) -> 661.688 | U12: =OFFSET('배치점수 계산기'!K$10,$D12,0) -> 660.147 | V12: =OFFSET('배치점수 계산기'!L$10,$D12,0) -> 656.62 | W12: =OFFSET('배치점수 계산기'!M$10,$D12,0) -> 표점 | X12: =OFFSET('배치점수 계산기'!N$10,$D12,0) -> 변표 | Y12: =OFFSET(환산공식!FW$15,$F12,0) -> 0.25 | Z12: =OFFSET(환산공식!FX$15,$F12,0) -> 0.38 | AA12: =OFFSET(환산공식!FY$15,$F12,0) -> 0.38 | AD12: =IF(L12="X",6,IF(Q12>R12,1,IF(Q12>S12,2,IF(Q12>T12,3,IF(Q12>U12,4,IF(Q12>=V12,5,IF(Q12<V12,6,""))))))) -> 6
C13: 가6 | D13: 6 | E13: 5 | F13: 5 | G13: 6 | H13: 가 | I13: 연세대 | J13: 생명공학과 | K13: 자연 | L13: =IF(OFFSET(환산공식!$ED$15,$F13,0)=1,"O","X") -> X | M13: =IFERROR(OFFSET(환산공식!DJ$15,$F13,0),"") -> 105.6 | N13: =IFERROR(CONCATENATE(ROUND(OFFSET(환산공식!DK$15,$F13,0),1),"%"),"") -> 100% | O13: =IFERROR(OFFSET(환산공식!DL$15,$F13,0),"") -> 0 | P13: =IF(E13="","",IF(Q13>R13,"90% 이상",IF(Q13>S13,CONCATENATE(ROUND(((Q13-S13)/(R13-S13))*20+70,0),"%"),IF(Q13>T13,CONCATENATE(ROUND(((Q13-T13)/(S13-T13))*30+40,0),"%"),IF(Q13>U13,CONCATENATE(ROUND(((Q13-U13)/(T13-U13))*30+10,0),"%"),IF(Q13>V13,CONCATENATE(ROUND(((Q13-V13)/(U13-V13))*7+3,0),"%"),"3% 이하")))))) -> 3% 이하 | Q13: =IFERROR(ROUND(OFFSET(환산공식!$FG$15,$F13,0),3),"") -> 0 | R13: =OFFSET('배치점수 계산기'!H$10,$D13,0) -> 663.82 | S13: =OFFSET('배치점수 계산기'!I$10,$D13,0) -> 663.169 | T13: =OFFSET('배치점수 계산기'!J$10,$D13,0) -> 661.688 | U13: =OFFSET('배치점수 계산기'!K$10,$D13,0) -> 656.726 | V13: =OFFSET('배치점수 계산기'!L$10,$D13,0) -> 653.339 | W13: =OFFSET('배치점수 계산기'!M$10,$D13,0) -> 표점 | X13: =OFFSET('배치점수 계산기'!N$10,$D13,0) -> 변표 | Y13: =OFFSET(환산공식!FW$15,$F13,0) -> 0.25 | Z13: =OFFSET(환산공식!FX$15,$F13,0) -> 0.38 | AA13: =OFFSET(환산공식!FY$15,$F13,0) -> 0.38 | AD13: =IF(L13="X",6,IF(Q13>R13,1,IF(Q13>S13,2,IF(Q13>T13,3,IF(Q13>U13,4,IF(Q13>=V13,5,IF(Q13<V13,6,""))))))) -> 6
C14: 가7 | D14: 7 | E14: 5 | F14: 5 | G14: 7 | H14: 가 | I14: 연세대 | J14: 산업공학과 | K14: 자연 | L14: =IF(OFFSET(환산공식!$ED$15,$F14,0)=1,"O","X") -> X | M14: =IFERROR(OFFSET(환산공식!DJ$15,$F14,0),"") -> 105.6 | N14: =IFERROR(CONCATENATE(ROUND(OFFSET(환산공식!DK$15,$F14,0),1),"%"),"") -> 100% | O14: =IFERROR(OFFSET(환산공식!DL$15,$F14,0),"") -> 0 | P14: =IF(E14="","",IF(Q14>R14,"90% 이상",IF(Q14>S14,CONCATENATE(ROUND(((Q14-S14)/(R14-S14))*20+70,0),"%"),IF(Q14>T14,CONCATENATE(ROUND(((Q14-T14)/(S14-T14))*30+40,0),"%"),IF(Q14>U14,CONCATENATE(ROUND(((Q14-U14)/(T14-U14))*30+10,0),"%"),IF(Q14>V14,CONCATENATE(ROUND(((Q14-V14)/(U14-V14))*7+3,0),"%"),"3% 이하")))))) -> 3% 이하 | Q14: =IFERROR(ROUND(OFFSET(환산공식!$FG$15,$F14,0),3),"") -> 0 | R14: =OFFSET('배치점수 계산기'!H$10,$D14,0) -> 664.392 | S14: =OFFSET('배치점수 계산기'!I$10,$D14,0) -> 663.169 | T14: =OFFSET('배치점수 계산기'!J$10,$D14,0) -> 661.494 | U14: =OFFSET('배치점수 계산기'!K$10,$D14,0) -> 657.291 | V14: =OFFSET('배치점수 계산기'!L$10,$D14,0) -> 654.49 | W14: =OFFSET('배치점수 계산기'!M$10,$D14,0) -> 표점 | X14: =OFFSET('배치점수 계산기'!N$10,$D14,0) -> 변표 | Y14: =OFFSET(환산공식!FW$15,$F14,0) -> 0.25 | Z14: =OFFSET(환산공식!FX$15,$F14,0) -> 0.38 | AA14: =OFFSET(환산공식!FY$15,$F14,0) -> 0.38 | AD14: =IF(L14="X",6,IF(Q14>R14,1,IF(Q14>S14,2,IF(Q14>T14,3,IF(Q14>U14,4,IF(Q14>=V14,5,IF(Q14<V14,6,""))))))) -> 6
C15: 가8 | D15: 8 | E15: 5 | F15: 5 | G15: 8 | H15: 가 | I15: 연세대 | J15: 화공생명공학부 | K15: 자연 | L15: =IF(OFFSET(환산공식!$ED$15,$F15,0)=1,"O","X") -> X | M15: =IFERROR(OFFSET(환산공식!DJ$15,$F15,0),"") -> 105.6 | N15: =IFERROR(CONCATENATE(ROUND(OFFSET(환산공식!DK$15,$F15,0),1),"%"),"") -> 100% | O15: =IFERROR(OFFSET(환산공식!DL$15,$F15,0),"") -> 0 | P15: =IF(E15="","",IF(Q15>R15,"90% 이상",IF(Q15>S15,CONCATENATE(ROUND(((Q15-S15)/(R15-S15))*20+70,0),"%"),IF(Q15>T15,CONCATENATE(ROUND(((Q15-T15)/(S15-T15))*30+40,0),"%"),IF(Q15>U15,CONCATENATE(ROUND(((Q15-U15)/(T15-U15))*30+10,0),"%"),IF(Q15>V15,CONCATENATE(ROUND(((Q15-V15)/(U15-V15))*7+3,0),"%"),"3% 이하")))))) -> 3% 이하 | Q15: =IFERROR(ROUND(OFFSET(환산공식!$FG$15,$F15,0),3),"") -> 0 | R15: =OFFSET('배치점수 계산기'!H$10,$D15,0) -> 663.169 | S15: =OFFSET('배치점수 계산기'!I$10,$D15,0) -> 662.536 | T15: =OFFSET('배치점수 계산기'!J$10,$D15,0) -> 661.072 | U15: =OFFSET('배치점수 계산기'!K$10,$D15,0) -> 656.726 | V15: =OFFSET('배치점수 계산기'!L$10,$D15,0) -> 652.759 | W15: =OFFSET('배치점수 계산기'!M$10,$D15,0) -> 표점 | X15: =OFFSET('배치점수 계산기'!N$10,$D15,0) -> 변표 | Y15: =OFFSET(환산공식!FW$15,$F15,0) -> 0.25 | Z15: =OFFSET(환산공식!FX$15,$F15,0) -> 0.38 | AA15: =OFFSET(환산공식!FY$15,$F15,0) -> 0.38 | AD15: =IF(L15="X",6,IF(Q15>R15,1,IF(Q15>S15,2,IF(Q15>T15,3,IF(Q15>U15,4,IF(Q15>=V15,5,IF(Q15<V15,6,""))))))) -> 6
C16: 가9 | D16: 9 | E16: 5 | F16: 5 | G16: 9 | H16: 가 | I16: 연세대 | J16: 생화학과 | K16: 자연 | L16: =IF(OFFSET(환산공식!$ED$15,$F16,0)=1,"O","X") -> X | M16: =IFERROR(OFFSET(환산공식!DJ$15,$F16,0),"") -> 105.6 | N16: =IFERROR(CONCATENATE(ROUND(OFFSET(환산공식!DK$15,$F16,0),1),"%"),"") -> 100% | O16: =IFERROR(OFFSET(환산공식!DL$15,$F16,0),"") -> 0 | P16: =IF(E16="","",IF(Q16>R16,"90% 이상",IF(Q16>S16,CONCATENATE(ROUND(((Q16-S16)/(R16-S16))*20+70,0),"%"),IF(Q16>T16,CONCATENATE(ROUND(((Q16-T16)/(S16-T16))*30+40,0),"%"),IF(Q16>U16,CONCATENATE(ROUND(((Q16-U16)/(T16-U16))*30+10,0),"%"),IF(Q16>V16,CONCATENATE(ROUND(((Q16-V16)/(U16-V16))*7+3,0),"%"),"3% 이하")))))) -> 3% 이하 | Q16: =IFERROR(ROUND(OFFSET(환산공식!$FG$15,$F16,0),3),"") -> 0 | R16: =OFFSET('배치점수 계산기'!H$10,$D16,0) -> 664.514 | S16: =OFFSET('배치점수 계산기'!I$10,$D16,0) -> 663.047 | T16: =OFFSET('배치점수 계산기'!J$10,$D16,0) -> 661.072 | U16: =OFFSET('배치점수 계산기'!K$10,$D16,0) -> 659.581 | V16: =OFFSET('배치점수 계산기'!L$10,$D16,0) -> 656.339 | W16: =OFFSET('배치점수 계산기'!M$10,$D16,0) -> 표점 | X16: =OFFSET('배치점수 계산기'!N$10,$D16,0) -> 변표 | Y16: =OFFSET(환산공식!FW$15,$F16,0) -> 0.25 | Z16: =OFFSET(환산공식!FX$15,$F16,0) -> 0.38 | AA16: =OFFSET(환산공식!FY$15,$F16,0) -> 0.38 | AD16: =IF(L16="X",6,IF(Q16>R16,1,IF(Q16>S16,2,IF(Q16>T16,3,IF(Q16>U16,4,IF(Q16>=V16,5,IF(Q16<V16,6,""))))))) -> 6
C17: 가10 | D17: 10 | E17: 5 | F17: 5 | G17: 10 | H17: 가 | I17: 연세대 | J17: 화학과 | K17: 자연 | L17: =IF(OFFSET(환산공식!$ED$15,$F17,0)=1,"O","X") -> X | M17: =IFERROR(OFFSET(환산공식!DJ$15,$F17,0),"") -> 105.6 | N17: =IFERROR(CONCATENATE(ROUND(OFFSET(환산공식!DK$15,$F17,0),1),"%"),"") -> 100% | O17: =IFERROR(OFFSET(환산공식!DL$15,$F17,0),"") -> 0 | P17: =IF(E17="","",IF(Q17>R17,"90% 이상",IF(Q17>S17,CONCATENATE(ROUND(((Q17-S17)/(R17-S17))*20+70,0),"%"),IF(Q17>T17,CONCATENATE(ROUND(((Q17-T17)/(S17-T17))*30+40,0),"%"),IF(Q17>U17,CONCATENATE(ROUND(((Q17-U17)/(T17-U17))*30+10,0),"%"),IF(Q17>V17,CONCATENATE(ROUND(((Q17-V17)/(U17-V17))*7+3,0),"%"),"3% 이하")))))) -> 3% 이하 | Q17: =IFERROR(ROUND(OFFSET(환산공식!$FG$15,$F17,0),3),"") -> 0 | R17: =OFFSET('배치점수 계산기'!H$10,$D17,0) -> 663.419 | S17: =OFFSET('배치점수 계산기'!I$10,$D17,0) -> 662.536 | T17: =OFFSET('배치점수 계산기'!J$10,$D17,0) -> 661.072 | U17: =OFFSET('배치점수 계산기'!K$10,$D17,0) -> 659.386 | V17: =OFFSET('배치점수 계산기'!L$10,$D17,0) -> 656.726 | W17: =OFFSET('배치점수 계산기'!M$10,$D17,0) -> 표점 | X17: =OFFSET('배치점수 계산기'!N$10,$D17,0) -> 변표 | Y17: =OFFSET(환산공식!FW$15,$F17,0) -> 0.25 | Z17: =OFFSET(환산공식!FX$15,$F17,0) -> 0.38 | AA17: =OFFSET(환산공식!FY$15,$F17,0) -> 0.38 | AD17: =IF(L17="X",6,IF(Q17>R17,1,IF(Q17>S17,2,IF(Q17>T17,3,IF(Q17>U17,4,IF(Q17>=V17,5,IF(Q17<V17,6,""))))))) -> 6
C18: 가11 | D18: 11 | E18: 5 | F18: 5 | G18: 11 | H18: 가 | I18: 연세대 | J18: 수학과 | K18: 자연 | L18: =IF(OFFSET(환산공식!$ED$15,$F18,0)=1,"O","X") -> X | M18: =IFERROR(OFFSET(환산공식!DJ$15,$F18,0),"") -> 105.6 | N18: =IFERROR(CONCATENATE(ROUND(OFFSET(환산공식!DK$15,$F18,0),1),"%"),"") -> 100% | O18: =IFERROR(OFFSET(환산공식!DL$15,$F18,0),"") -> 0 | P18: =IF(E18="","",IF(Q18>R18,"90% 이상",IF(Q18>S18,CONCATENATE(ROUND(((Q18-S18)/(R18-S18))*20+70,0),"%"),IF(Q18>T18,CONCATENATE(ROUND(((Q18-T18)/(S18-T18))*30+40,0),"%"),IF(Q18>U18,CONCATENATE(ROUND(((Q18-U18)/(T18-U18))*30+10,0),"%"),IF(Q18>V18,CONCATENATE(ROUND(((Q18-V18)/(U18-V18))*7+3,0),"%"),"3% 이하")))))) -> 3% 이하 | Q18: =IFERROR(ROUND(OFFSET(환산공식!$FG$15,$F18,0),3),"") -> 0 | R18: =OFFSET('배치점수 계산기'!H$10,$D18,0) -> 663.419 | S18: =OFFSET('배치점수 계산기'!I$10,$D18,0) -> 662.35 | T18: =OFFSET('배치점수 계산기'!J$10,$D18,0) -> 660.674 | U18: =OFFSET('배치점수 계산기'!K$10,$D18,0) -> 659.386 | V18: =OFFSET('배치점수 계산기'!L$10,$D18,0) -> 656.62 | W18: =OFFSET('배치점수 계산기'!M$10,$D18,0) -> 표점 | X18: =OFFSET('배치점수 계산기'!N$10,$D18,0) -> 변표 | Y18: =OFFSET(환산공식!FW$15,$F18,0) -> 0.25 | Z18: =OFFSET(환산공식!FX$15,$F18,0) -> 0.38 | AA18: =OFFSET(환산공식!FY$15,$F18,0) -> 0.38 | AD18: =IF(L18="X",6,IF(Q18>R18,1,IF(Q18>S18,2,IF(Q18>T18,3,IF(Q18>U18,4,IF(Q18>=V18,5,IF(Q18<V18,6,""))))))) -> 6
C19: 가12 | D19: 12 | E19: 5 | F19: 5 | G19: 12 | H19: 가 | I19: 연세대 | J19: 지능형반도체전공 | K19: 자연 | L19: =IF(OFFSET(환산공식!$ED$15,$F19,0)=1,"O","X") -> X | M19: =IFERROR(OFFSET(환산공식!DJ$15,$F19,0),"") -> 105.6 | N19: =IFERROR(CONCATENATE(ROUND(OFFSET(환산공식!DK$15,$F19,0),1),"%"),"") -> 100% | O19: =IFERROR(OFFSET(환산공식!DL$15,$F19,0),"") -> 0 | P19: =IF(E19="","",IF(Q19>R19,"90% 이상",IF(Q19>S19,CONCATENATE(ROUND(((Q19-S19)/(R19-S19))*20+70,0),"%"),IF(Q19>T19,CONCATENATE(ROUND(((Q19-T19)/(S19-T19))*30+40,0),"%"),IF(Q19>U19,CONCATENATE(ROUND(((Q19-U19)/(T19-U19))*30+10,0),"%"),IF(Q19>V19,CONCATENATE(ROUND(((Q19-V19)/(U19-V19))*7+3,0),"%"),"3% 이하")))))) -> 3% 이하 | Q19: =IFERROR(ROUND(OFFSET(환산공식!$FG$15,$F19,0),3),"") -> 0 | R19: =OFFSET('배치점수 계산기'!H$10,$D19,0) -> 663.169 | S19: =OFFSET('배치점수 계산기'!I$10,$D19,0) -> 662.536 | T19: =OFFSET('배치점수 계산기'!J$10,$D19,0) -> 660.147 | U19: =OFFSET('배치점수 계산기'!K$10,$D19,0) -> 657.291 | V19: =OFFSET('배치점수 계산기'!L$10,$D19,0) -> 654.49 | W19: =OFFSET('배치점수 계산기'!M$10,$D19,0) -> 표점 | X19: =OFFSET('배치점수 계산기'!N$10,$D19,0) -> 변표 | Y19: =OFFSET(환산공식!FW$15,$F19,0) -> 0.25 | Z19: =OFFSET(환산공식!FX$15,$F19,0) -> 0.38 | AA19: =OFFSET(환산공식!FY$15,$F19,0) -> 0.38 | AD19: =IF(L19="X",6,IF(Q19>R19,1,IF(Q19>S19,2,IF(Q19>T19,3,IF(Q19>U19,4,IF(Q19>=V19,5,IF(Q19<V19,6,""))))))) -> 6
C20: 가13 | D20: 13 | E20: 5 | F20: 5 | G20: 13 | H20: 가 | I20: 연세대 | J20: 디스플레이융합공학과 | K20: 자연 | L20: =IF(OFFSET(환산공식!$ED$15,$F20,0)=1,"O","X") -> X | M20: =IFERROR(OFFSET(환산공식!DJ$15,$F20,0),"") -> 105.6 | N20: =IFERROR(CONCATENATE(ROUND(OFFSET(환산공식!DK$15,$F20,0),1),"%"),"") -> 100% | O20: =IFERROR(OFFSET(환산공식!DL$15,$F20,0),"") -> 0 | P20: =IF(E20="","",IF(Q20>R20,"90% 이상",IF(Q20>S20,CONCATENATE(ROUND(((Q20-S20)/(R20-S20))*20+70,0),"%"),IF(Q20>T20,CONCATENATE(ROUND(((Q20-T20)/(S20-T20))*30+40,0),"%"),IF(Q20>U20,CONCATENATE(ROUND(((Q20-U20)/(T20-U20))*30+10,0),"%"),IF(Q20>V20,CONCATENATE(ROUND(((Q20-V20)/(U20-V20))*7+3,0),"%"),"3% 이하")))))) -> 3% 이하 | Q20: =IFERROR(ROUND(OFFSET(환산공식!$FG$15,$F20,0),3),"") -> 0 | R20: =OFFSET('배치점수 계산기'!H$10,$D20,0) -> 661.688 | S20: =OFFSET('배치점수 계산기'!I$10,$D20,0) -> 660.674 | T20: =OFFSET('배치점수 계산기'!J$10,$D20,0) -> 657.803 | U20: =OFFSET('배치점수 계산기'!K$10,$D20,0) -> 657.027 | V20: =OFFSET('배치점수 계산기'!L$10,$D20,0) -> 652.847 | W20: =OFFSET('배치점수 계산기'!M$10,$D20,0) -> 표점 | X20: =OFFSET('배치점수 계산기'!N$10,$D20,0) -> 변표 | Y20: =OFFSET(환산공식!FW$15,$F20,0) -> 0.25 | Z20: =OFFSET(환산공식!FX$15,$F20,0) -> 0.38 | AA20: =OFFSET(환산공식!FY$15,$F20,0) -> 0.38 | AD20: =IF(L20="X",6,IF(Q20>R20,1,IF(Q20>S20,2,IF(Q20>T20,3,IF(Q20>U20,4,IF(Q20>=V20,5,IF(Q20<V20,6,""))))))) -> 6
... C932: 가925 | D932: 993 | E932: 243 | F932: 243 | G932: 925 | H932: 가 | I932: 한국교원대 | J932: 초등교육 | K932: 통합 | L932: =IF(OFFSET(환산공식!$ED$15,$F932,0)=1,"O","X") -> X | M932: =IFERROR(OFFSET(환산공식!DJ$15,$F932,0),"") -> 100 | N932: =IFERROR(CONCATENATE(ROUND(OFFSET(환산공식!DK$15,$F932,0),1),"%"),"") -> 100% | O932: =IFERROR(OFFSET(환산공식!DL$15,$F932,0),"") -> 0 | P932: =IF(E932="","",IF(Q932>R932,"90% 이상",IF(Q932>S932,CONCATENATE(ROUND(((Q932-S932)/(R932-S932))*20+70,0),"%"),IF(Q932>T932,CONCATENATE(ROUND(((Q932-T932)/(S932-T932))*30+40,0),"%"),IF(Q932>U932,CONCATENATE(ROUND(((Q932-U932)/(T932-U932))*30+10,0),"%"),IF(Q932>V932,CONCATENATE(ROUND(((Q932-V932)/(U932-V932))*7+3,0),"%"),"3% 이하")))))) -> 3% 이하 | Q932: =IFERROR(ROUND(OFFSET(환산공식!$FG$15,$F932,0),3),"") -> 0 | R932: =OFFSET('배치점수 계산기'!H$10,$D932,0) -> 368.95 | S932: =OFFSET('배치점수 계산기'!I$10,$D932,0) -> 365.515 | T932: =OFFSET('배치점수 계산기'!J$10,$D932,0) -> 361.775 | U932: =OFFSET('배치점수 계산기'!K$10,$D932,0) -> 357.485 | V932: =OFFSET('배치점수 계산기'!L$10,$D932,0) -> 352.21 | W932: =OFFSET('배치점수 계산기'!M$10,$D932,0) -> 백분위 | X932: =OFFSET('배치점수 계산기'!N$10,$D932,0) -> 백분위 | Y932: =OFFSET(환산공식!FW$15,$F932,0) -> 0.37 | Z932: =OFFSET(환산공식!FX$15,$F932,0) -> 0.33 | AA932: =OFFSET(환산공식!FY$15,$F932,0) -> 0.3 | AD932: =IF(L932="X",6,IF(Q932>R932,1,IF(Q932>S932,2,IF(Q932>T932,3,IF(Q932>U932,4,IF(Q932>=V932,5,IF(Q932<V932,6,""))))))) -> 6

Sheet        나 군       
B1: 가 | C1: 나 | D1: 다 | E1: 가나다 | I1: 환산점수 배치표 (나 군) 2026학년도 수능 실채점기준
B2: 1 | C2: 2 | D2: 3 | E2: 4 | R2: 제작 및 검토 <베텔기우스> Betelgeuse058.tistory.com
B3: 군 입력
B4: 2 | C4: =IF($B$4=1,CONCATENATE($B$1,AE4),IF($B$4=2,CONCATENATE($C$1,AE4),IF($B$4=3,CONCATENATE($D$1,AE4),IF($B$4=4,CONCATENATE($E$1,AE4))))) -> 나
C5: =IFERROR(INDEX('배치점수 계산기'!A9:C9,MATCH(C4,'배치점수 계산기'!A7:C7,0)),) -> 992 | R5: 판정 기준점수
M6: 감점 상세 | P6: 나의 점수 | R6: 안정 | S6: 적정 | T6: 예상컷 | U6: 도전 | W6: 반영 방법 | Y6: 실질 반영비
E7: 공식 연번 | H7: 모집군 | I7: 대학 | J7: 학과 | K7: 계열 | L7: 지원가능 | M7: 영어감점 | N7: 영어감점 비율 | O7: 한국사/외국어 | P7: 합격확률 추정 | Q7: 환산점수 | R7: 0.9 | S7: 0.7 | T7: 0.4 | U7: 0.1 | V7: 0.03 | W7: 국 수 | X7: 탐구 | Y7: 국 | Z7: 수 | AA7: 탐 | AD7: 서식기준
C8: =_xlfn.CONCAT($C$4,G8) -> 나1 | D8: =MATCH($C8,'배치점수 계산기'!$O$11:$O$3001,0) -> 994 | E8: =OFFSET('배치점수 계산기'!A$10,D8,0) -> 2 | F8: =MATCH(E8,환산공식!$C$16:$C$903,0) -> 2 | G8: 1 | H8: =IFERROR(INDEX('배치점수 계산기'!C$11:C$3001,MATCH($C8,'배치점수 계산기'!$O$11:$O$3001,0)),"") -> 나 | I8: =IFERROR(INDEX('배치점수 계산기'!D$11:D$3001,MATCH($C8,'배치점수 계산기'!$O$11:$O$3001,0)),"") -> 서울대 | J8: =IFERROR(INDEX('배치점수 계산기'!E$11:E$3001,MATCH($C8,'배치점수 계산기'!$O$11:$O$3001,0)),"") -> 컴퓨터공학부 | K8: =IFERROR(INDEX('배치점수 계산기'!F$11:F$3001,MATCH($C8,'배치점수 계산기'!$O$11:$O$3001,0)),"") -> 자연 | L8: =IF(OFFSET(환산공식!$ED$15,$F8,0)=1,"O","X") -> X | M8: =IFERROR(OFFSET(환산공식!DJ$15,$F8,0),"") -> 0 | N8: =IFERROR(CONCATENATE(ROUND(OFFSET(환산공식!DK$15,$F8,0),1),"%"),"") | O8: =IFERROR(OFFSET(환산공식!DL$15,$F8,0),"") -> 0 | P8: =IF(E8="","",IF(Q8>R8,"90% 이상",IF(Q8>S8,CONCATENATE(ROUND(((Q8-S8)/(R8-S8))*20+70,0),"%"),IF(Q8>T8,CONCATENATE(ROUND(((Q8-T8)/(S8-T8))*30+40,0),"%"),IF(Q8>U8,CONCATENATE(ROUND(((Q8-U8)/(T8-U8))*30+10,0),"%"),IF(Q8>V8,CONCATENATE(ROUND(((Q8-V8)/(U8-V8))*7+3,0),"%"),"3% 이하")))))) -> 3% 이하 | Q8: =IFERROR(ROUND(OFFSET(환산공식!$FG$15,$F8,0),3),"") -> 0 | R8: =OFFSET('배치점수 계산기'!H$10,$D8,0) -> 416.052 | S8: =OFFSET('배치점수 계산기'!I$10,$D8,0) -> 412.532 | T8: =OFFSET('배치점수 계산기'!J$10,$D8,0) -> 409.284 | U8: =OFFSET('배치점수 계산기'!K$10,$D8,0) -> 405.686 | V8: =OFFSET('배치점수 계산기'!L$10,$D8,0) -> 400.318 | W8: =OFFSET('배치점수 계산기'!M$10,$D8,0) -> 표점 | X8: =OFFSET('배치점수 계산기'!N$10,$D8,0) -> 표점 | Y8: =OFFSET(환산공식!FW$15,$F8,0) -> 0.33 | Z8: =OFFSET(환산공식!FX$15,$F8,0) -> 0.4 | AA8: =OFFSET(환산공식!FY$15,$F8,0) -> 0.27 | AD8: =IF(L8="X",6,IF(Q8>R8,1,IF(Q8>S8,2,IF(Q8>T8,3,IF(Q8>U8,4,IF(Q8>=V8,5,IF(Q8<V8,6,""))))))) -> 6
C9: 나2 | D9: 995 | E9: 2 | F9: 2 | G9: 2 | H9: 나 | I9: 서울대 | J9: 수리과학부 | K9: 자연 | L9: =IF(OFFSET(환산공식!$ED$15,$F9,0)=1,"O","X") -> X | M9: =IFERROR(OFFSET(환산공식!DJ$15,$F9,0),"") -> 0 | N9: =IFERROR(CONCATENATE(ROUND(OFFSET(환산공식!DK$15,$F9,0),1),"%"),"") | O9: =IFERROR(OFFSET(환산공식!DL$15,$F9,0),"") -> 0 | P9: =IF(E9="","",IF(Q9>R9,"90% 이상",IF(Q9>S9,CONCATENATE(ROUND(((Q9-S9)/(R9-S9))*20+70,0),"%"),IF(Q9>T9,CONCATENATE(ROUND(((Q9-T9)/(S9-T9))*30+40,0),"%"),IF(Q9>U9,CONCATENATE(ROUND(((Q9-U9)/(T9-U9))*30+10,0),"%"),IF(Q9>V9,CONCATENATE(ROUND(((Q9-V9)/(U9-V9))*7+3,0),"%"),"3% 이하")))))) -> 3% 이하 | Q9: =IFERROR(ROUND(OFFSET(환산공식!$FG$15,$F9,0),3),"") -> 0 | R9: =OFFSET('배치점수 계산기'!H$10,$D9,0) -> 413.976 | S9: =OFFSET('배치점수 계산기'!I$10,$D9,0) -> 412.672 | T9: =OFFSET('배치점수 계산기'!J$10,$D9,0) -> 409.284 | U9: =OFFSET('배치점수 계산기'!K$10,$D9,0) -> 405.436 | V9: =OFFSET('배치점수 계산기'!L$10,$D9,0) -> 403.22 | W9: =OFFSET('배치점수 계산기'!M$10,$D9,0) -> 표점 | X9: =OFFSET('배치점수 계산기'!N$10,$D9,0) -> 표점 | Y9: =OFFSET(환산공식!FW$15,$F9,0) -> 0.33 | Z9: =OFFSET(환산공식!FX$15,$F9,0) -> 0.4 | AA9: =OFFSET(환산공식!FY$15,$F9,0) -> 0.27 | AD9: =IF(L9="X",6,IF(Q9>R9,1,IF(Q9>S9,2,IF(Q9>T9,3,IF(Q9>U9,4,IF(Q9>=V9,5,IF(Q9<V9,6,""))))))) -> 6
C10: 나3 | D10: 996 | E10: 2 | F10: 2 | G10: 3 | H10: 나 | I10: 서울대 | J10: 통계학과 | K10: 자연 | L10: =IF(OFFSET(환산공식!$ED$15,$F10,0)=1,"O","X") -> X | M10: =IFERROR(OFFSET(환산공식!DJ$15,$F10,0),"") -> 0 | N10: =IFERROR(CONCATENATE(ROUND(OFFSET(환산공식!DK$15,$F10,0),1),"%"),"") | O10: =IFERROR(OFFSET(환산공식!DL$15,$F10,0),"") -> 0 | P10: =IF(E10="","",IF(Q10>R10,"90% 이상",IF(Q10>S10,CONCATENATE(ROUND(((Q10-S10)/(R10-S10))*20+70,0),"%"),IF(Q10>T10,CONCATENATE(ROUND(((Q10-T10)/(S10-T10))*30+40,0),"%"),IF(Q10>U10,CONCATENATE(ROUND(((Q10-U10)/(T10-U10))*30+10,0),"%"),IF(Q10>V10,CONCATENATE(ROUND(((Q10-V10)/(U10-V10))*7+3,0),"%"),"3% 이하")))))) -> 3% 이하 | Q10: =IFERROR(ROUND(OFFSET(환산공식!$FG$15,$F10,0),3),"") -> 0 | R10: =OFFSET('배치점수 계산기'!H$10,$D10,0) -> 408.982 | S10: =OFFSET('배치점수 계산기'!I$10,$D10,0) -> 407.306 | T10: =OFFSET('배치점수 계산기'!J$10,$D10,0) -> 405.686 | U10: =OFFSET('배치점수 계산기'!K$10,$D10,0) -> 403.22 | V10: =OFFSET('배치점수 계산기'!L$10,$D10,0) -> 400.598 | W10: =OFFSET('배치점수 계산기'!M$10,$D10,0) -> 표점 | X10: =OFFSET('배치점수 계산기'!N$10,$D10,0) -> 표점 | Y10: =OFFSET(환산공식!FW$15,$F10,0) -> 0.33 | Z10: =OFFSET(환산공식!FX$15,$F10,0) -> 0.4 | AA10: =OFFSET(환산공식!FY$15,$F10,0) -> 0.27 | AD10: =IF(L10="X",6,IF(Q10>R10,1,IF(Q10>S10,2,IF(Q10>T10,3,IF(Q10>U10,4,IF(Q10>=V10,5,IF(Q10<V10,6,""))))))) -> 6
